<?xml version="1.0" ?>
<!-- =================================================================================== -->
<!-- |    This document was autogenerated by xacro from /home/turtlebot7/gp_ws/src/turtleGripper/all_descriptions/tgrip_description/urdf/tgrip.urdf.xacro | -->
<!-- |    EDITING THIS FILE BY HAND IS NOT RECOMMENDED                                 | -->
<!-- =================================================================================== -->
<robot name="tgrip" xmlns:xacro="http://ros.org/wiki/xacro">
    <!-- 
    These properties must be observed by any machine
    that wants to be defined as a turtlebot. Refer
    to the REP for more details.
    
    http://www.ros.org/reps/rep-0119.html
   -->
    <!-- 
    These properties must be observed by any machine
    that wants to be defined as a turtlebot. Refer
    to the REP for more details.
    
    http://www.ros.org/reps/rep-0119.html
   -->
    <!-- <gazebo reference="hokuyo_link"> -->
    <gazebo reference="laser">
        <sensor name="head_hokuyo_sensor" type="gpu_ray">
            <pose>0 0 0 0 0 0</pose>
            <visualize>false</visualize>
            <update_rate>40</update_rate>
            <ray>
                <scan>
                    <horizontal>
                        <samples>720</samples>
                        <resolution>1</resolution>
                        <min_angle>-1.570796</min_angle>
                        <max_angle>1.570796</max_angle>
                    </horizontal>
                </scan>
                <range>
                    <min>0.10</min>
                    <max>30.0</max>
                    <resolution>0.01</resolution>
                </range>
                <noise>
                    <type>gaussian</type>
                    <!-- Noise parameters based on published spec for Hokuyo laser
               achieving "+-30mm" accuracy at range < 10m.  A mean of 0.0m and
               stddev of 0.01m will put 99.7% of samples within 0.03m of the true
               reading. -->
                    <mean>0.0</mean>
                    <stddev>0.01</stddev>
                </noise>
            </ray>
            <plugin filename="libgazebo_ros_gpu_laser.so" name="gazebo_ros_head_hokuyo_controller">
                <!-- <topicName>/rrbot/laser/scan</topicName> -->
                <topicName>/scan</topicName>
                <!-- <frameName>hokuyo_link</frameName> -->
                <frameName>laser</frameName>
            </plugin>
        </sensor>
    </gazebo>
    <!-- 
    These properties must be observed by any machine
    that wants to be defined as a turtlebot. Refer
    to the REP for more details.
    
    http://www.ros.org/reps/rep-0119.html
   -->
    <material name="black">
        <color rgba="0.0 0.0 0.0 1.0" />
    </material>
    <material name="white">
        <color rgba="1.0 1.0 1.0 1.0" />
    </material>
    <material name="red">
        <color rgba="0.8 0.0 0.0 1.0" />
    </material>
    <material name="blue">
        <color rgba="0.0 0.0 0.8 1.0" />
    </material>
    <material name="green">
        <color rgba="0.0 0.8 0.0 1.0" />
    </material>
    <material name="grey">
        <color rgba="0.5 0.5 0.5 1.0" />
    </material>
    <material name="orange">
        <color rgba="1.0 0.423529411765 0.0392156862745 1.0" />
    </material>
    <material name="brown">
        <color rgba="0.870588235294 0.811764705882 0.764705882353 1.0" />
    </material>
    <!-- World -->
    <gazebo reference="world" />
    <gazebo reference="link1">
        <kp>1000000.0</kp>
        <kd>100.0</kd>
        <mu1>30.0</mu1>
        <mu2>30.0</mu2>
        <maxVel>1.0</maxVel>
        <minDepth>0.001</minDepth>
        <material>Gazebo/DarkGrey</material>
    </gazebo>
    <gazebo reference="link2">
        <kp>1000000.0</kp>
        <kd>100.0</kd>
        <mu1>30.0</mu1>
        <mu2>30.0</mu2>
        <maxVel>1.0</maxVel>
        <minDepth>0.001</minDepth>
        <material>Gazebo/DarkGrey</material>
    </gazebo>
    <gazebo reference="link3">
        <kp>1000000.0</kp>
        <kd>100.0</kd>
        <mu1>30.0</mu1>
        <mu2>30.0</mu2>
        <maxVel>1.0</maxVel>
        <minDepth>0.001</minDepth>
        <material>Gazebo/DarkGrey</material>
    </gazebo>
    <gazebo reference="link4">
        <kp>1000000.0</kp>
        <kd>100.0</kd>
        <mu1>30.0</mu1>
        <mu2>30.0</mu2>
        <maxVel>1.0</maxVel>
        <minDepth>0.001</minDepth>
        <material>Gazebo/DarkGrey</material>
    </gazebo>
    <gazebo reference="link5">
        <kp>1000000.0</kp>
        <kd>100.0</kd>
        <mu1>30.0</mu1>
        <mu2>30.0</mu2>
        <maxVel>1.0</maxVel>
        <minDepth>0.001</minDepth>
        <material>Gazebo/DarkGrey</material>
    </gazebo>
    <gazebo reference="gripper_link">
        <kp>1000000.0</kp>
        <kd>100.0</kd>
        <mu1>30.0</mu1>
        <mu2>30.0</mu2>
        <maxVel>1.0</maxVel>
        <minDepth>0.001</minDepth>
        <material>Gazebo/DarkGrey</material>
    </gazebo>
    <gazebo reference="gripper_link_sub">
        <kp>1000000.0</kp>
        <kd>100.0</kd>
        <mu1>30.0</mu1>
        <mu2>30.0</mu2>
        <maxVel>1.0</maxVel>
        <minDepth>0.001</minDepth>
        <material>Gazebo/DarkGrey</material>
    </gazebo>
    <!-- end effector link -->
    <gazebo reference="end_effector_link">
        <material>Gazebo/Red</material>
    </gazebo>
    <!-- ros_control plugin -->
    <gazebo>
        <plugin filename="libgazebo_ros_control.so" name="gazebo_ros_control">
            <controlPeriod>0.001</controlPeriod>
            <robotSimType>gazebo_ros_control/DefaultRobotHWSim</robotSimType>
            <legacyModeNS>true</legacyModeNS>
        </plugin>
    </gazebo>
    <gazebo>
        <!-- loading plugin: mimic joints works in gazebo now -->
        <plugin filename="libroboticsgroup_gazebo_mimic_joint_plugin.so" name="gazebo_gripper_ros_control">
            <joint>gripper</joint>
            <mimicJoint>gripper_sub</mimicJoint>
            <multiplier>1.0</multiplier>
            <offset>0.0</offset>
        </plugin>
    </gazebo>
    <!-- camera -->
    <transmission name="tran1">
        <type>transmission_interface/SimpleTransmission</type>
        <joint name="joint1">
            <hardwareInterface>hardware_interface/PositionJointInterface</hardwareInterface>
        </joint>
        <actuator name="motor1">
            <mechanicalReduction>1</mechanicalReduction>
        </actuator>
    </transmission>
    <transmission name="tran2">
        <type>transmission_interface/SimpleTransmission</type>
        <joint name="joint2">
            <hardwareInterface>hardware_interface/PositionJointInterface</hardwareInterface>
        </joint>
        <actuator name="motor2">
            <mechanicalReduction>1</mechanicalReduction>
        </actuator>
    </transmission>
    <transmission name="tran3">
        <type>transmission_interface/SimpleTransmission</type>
        <joint name="joint3">
            <hardwareInterface>hardware_interface/PositionJointInterface</hardwareInterface>
        </joint>
        <actuator name="motor3">
            <mechanicalReduction>1</mechanicalReduction>
        </actuator>
    </transmission>
    <transmission name="tran4">
        <type>transmission_interface/SimpleTransmission</type>
        <joint name="joint4">
            <hardwareInterface>hardware_interface/PositionJointInterface</hardwareInterface>
        </joint>
        <actuator name="motor4">
            <mechanicalReduction>1</mechanicalReduction>
        </actuator>
    </transmission>
    <transmission name="tran5">
        <type>transmission_interface/SimpleTransmission</type>
        <joint name="gripper">
            <hardwareInterface>hardware_interface/EffortJointInterface</hardwareInterface>
        </joint>
        <actuator name="motor5">
            <mechanicalReduction>1</mechanicalReduction>
        </actuator>
    </transmission>
    <transmission name="tran6">
        <type>transmission_interface/SimpleTransmission</type>
        <joint name="gripper_sub">
            <hardwareInterface>hardware_interface/EffortJointInterface</hardwareInterface>
        </joint>
        <actuator name="motor6">
            <mechanicalReduction>1</mechanicalReduction>
        </actuator>
    </transmission>
    <!-- Link 1 -->
    <link name="link1">
        <visual>
            <origin rpy="0 0 0" xyz="0 0 0" />
            <geometry>
                <mesh filename="package://open_manipulator_description/meshes/chain_link1.stl" scale="0.001 0.001 0.001" />
            </geometry>
            <material name="grey" />
        </visual>
        <collision>
            <origin rpy="0 0 0" xyz="0 0 0" />
            <geometry>
                <mesh filename="package://open_manipulator_description/meshes/chain_link1.stl" scale="0.001 0.001 0.001" />
            </geometry>
        </collision>
        
<inertial>
            <origin xyz="3.0876154e-04 0.0000000e+00 -1.2176461e-04" />
            <mass value="7.9119962e-02" />
            <inertia ixx="1.2505234e-05" ixy="0.0" ixz="-1.7855208e-07" iyy="2.1898364e-05" iyz="0.0" izz="1.9267361e-05" />
        </inertial>

    </link>
    <!-- Joint 1 -->
    <joint name="joint1" type="revolute">
        <parent link="link1" />
        <child link="link2" />
        <origin rpy="0 0 0" xyz="0.012 0.0 0.017" />
        <axis xyz="0 0 1" />
        <limit effort="1" lower="-2.82743338823" upper="2.82743338823" velocity="4.8" />
    </joint>
    <!--  Link 2 -->
    <link name="link2">
        <visual>
            <origin rpy="0 0 0" xyz="0 0 0.019" />
            <geometry>
                <mesh filename="package://open_manipulator_description/meshes/chain_link2.stl" scale="0.001 0.001 0.001" />
            </geometry>
            <material name="grey" />
        </visual>
        <collision>
            <origin rpy="0 0 0" xyz="0 0 0.019" />
            <geometry>
                <mesh filename="package://open_manipulator_description/meshes/chain_link2.stl" scale="0.001 0.001 0.001" />
            </geometry>
        </collision>
        
<inertial>
            <origin xyz="-3.0184870e-04 5.4043684e-04 0.047433464" />
            <mass value="9.8406837e-02" />
            <inertia ixx="3.4543422e-05" ixy="-1.6031095e-08" ixz="-3.8375155e-07" iyy="3.2689329e-05" iyz="2.8511935e-08" izz="1.8850320e-05" />
        </inertial>

    </link>
    <!--  Joint 2 -->
    <joint name="joint2" type="revolute">
        <parent link="link2" />
        <child link="link3" />
        <origin rpy="0 0 0" xyz="0.0 0.0 0.0595" />
        <axis xyz="0 1 0" />
        <limit effort="1" lower="-1.79070781255" upper="1.57079632679" velocity="4.8" />
    </joint>
    <!--  Link 3 -->
    <link name="link3">
        <visual>
            <origin rpy="0 0 0" xyz="0 0 0" />
            <geometry>
                <mesh filename="package://open_manipulator_description/meshes/chain_link3.stl" scale="0.001 0.001 0.001" />
            </geometry>
            <material name="grey" />
        </visual>
        <collision>
            <origin rpy="0 0 0" xyz="0 0 0" />
            <geometry>
                <mesh filename="package://open_manipulator_description/meshes/chain_link3.stl" scale="0.001 0.001 0.001" />
            </geometry>
        </collision>
        
<inertial>
            <origin xyz="1.0308393e-02 3.7743363e-04 1.0170197e-01" />
            <mass value="1.3850917e-01" />
            <inertia ixx="3.3055381e-04" ixy="-9.7940978e-08" ixz="-3.8505711e-05" iyy="3.4290447e-04" iyz="-1.5717516e-06" izz="6.0346498e-05" />
        </inertial>

    </link>
    <!--  Joint 3 -->
    <joint name="joint3" type="revolute">
        <parent link="link3" />
        <child link="link4" />
        <origin rpy="0 0 0" xyz="0.024 0 0.128" />
        <axis xyz="0 1 0" />
        <limit effort="1" lower="-0.942477796077" upper="1.38230076758" velocity="4.8" />
    </joint>
    <!--  Link 4 -->
    <link name="link4">
        <visual>
            <origin rpy="0 0 0" xyz="0 0 0" />
            <geometry>
                <mesh filename="package://open_manipulator_description/meshes/chain_link4.stl" scale="0.001 0.001 0.001" />
            </geometry>
            <material name="grey" />
        </visual>
        <collision>
            <origin rpy="0 0 0" xyz="0 0 0" />
            <geometry>
                <mesh filename="package://open_manipulator_description/meshes/chain_link4.stl" scale="0.001 0.001 0.001" />
            </geometry>
        </collision>
        
<inertial>
            <origin xyz="9.0909590e-02 3.8929816e-04 2.2413279e-04" />
            <mass value="1.3274562e-01" />
            <inertia ixx="3.0654178e-05" ixy="-1.2764155e-06" ixz="-2.6874417e-07" iyy="2.4230292e-04" iyz="1.1559550e-08" izz="2.5155057e-04" />
        </inertial>

    </link>
    <!--  Joint 4 -->
    <joint name="joint4" type="revolute">
        <parent link="link4" />
        <child link="link5" />
        <origin rpy="0 0 0" xyz="0.124 0.0 0.0" />
        <axis xyz="0 1 0" />
        <limit effort="1" lower="-1.79070781255" upper="2.04203522483" velocity="4.8" />
    </joint>
    <!--  Link 5 -->
    <link name="link5">
        <visual>
            <origin rpy="0 0 0" xyz="0 0 0" />
            <geometry>
                <mesh filename="package://open_manipulator_description/meshes/chain_link5.stl" scale="0.001 0.001 0.001" />
            </geometry>
            <material name="grey" />
        </visual>
        <collision>
            <origin rpy="0 0 0" xyz="0 0 0" />
            <geometry>
                <mesh filename="package://open_manipulator_description/meshes/chain_link5.stl" scale="0.001 0.001 0.001" />
            </geometry>
        </collision>
        
<inertial>
            <origin xyz="4.4206755e-02 3.6839985e-07 8.9142216e-03" />
            <mass value="1.4327573e-01" />
            <inertia ixx="8.0870749e-05" ixy="0.0" ixz="-1.0157896e-06" iyy="7.5980465e-05" iyz="0.0" izz="9.3127351e-05" />
        </inertial>

    </link>
    <!--  Gripper joint -->
    <joint name="gripper" type="prismatic">
        <parent link="link5" />
        <child link="gripper_link" />
        <origin rpy="0 0 0" xyz="0.0817 0.021 0.0" />
        <axis xyz="0 1 0" />
        <limit effort="1" lower="-0.010" upper="0.019" velocity="4.8" />
    </joint>
    <!--  Gripper link -->
    <link name="gripper_link">
        <visual>
            <origin rpy="0 0 0" xyz="0.0 0.0 0" />
            <geometry>
                <mesh filename="package://open_manipulator_description/meshes/chain_link_grip_l.stl" scale="0.001 0.001 0.001" />
            </geometry>
            <material name="grey" />
        </visual>
        <collision>
            <origin rpy="0 0 0" xyz="0.0 0.0 0" />
            <geometry>
                <mesh filename="package://open_manipulator_description/meshes/chain_link_grip_l.stl" scale="0.001 0.001 0.001" />
            </geometry>
        </collision>
        
<inertial>
            <origin xyz="0 0 0" />
            <mass value="1.0e-03" />
            <inertia ixx="1.0e-03" ixy="0.0" ixz="0.0" iyy="1.0e-03" iyz="0.0" izz="1.0e-03" />
        </inertial>

    </link>
    <!--  Gripper joint sub -->
    <joint name="gripper_sub" type="prismatic">
        <parent link="link5" />
        <child link="gripper_link_sub" />
        <origin rpy="0 0 0" xyz="0.0817 -0.021 0" />
        <axis xyz="0 -1 0" />
        <limit effort="1" lower="-0.010" upper="0.019" velocity="4.8" />
        <mimic joint="gripper" multiplier="1" />
    </joint>
    <!--  Gripper link sub -->
    <link name="gripper_link_sub">
        <visual>
            <origin rpy="0 0 0" xyz="0.0 -0.0 0" />
            <geometry>
                <mesh filename="package://open_manipulator_description/meshes/chain_link_grip_r.stl" scale="0.001 0.001 0.001" />
            </geometry>
            <material name="grey" />
        </visual>
        <collision>
            <origin rpy="0 0 0" xyz="0.0 -0.0 0" />
            <geometry>
                <mesh filename="package://open_manipulator_description/meshes/chain_link_grip_r.stl" scale="0.001 0.001 0.001" />
            </geometry>
        </collision>
        
<inertial>
            <origin xyz="0 0 0" />
            <mass value="1.0e-03" />
            <inertia ixx="1.0e-03" ixy="0.0" ixz="0.0" iyy="1.0e-03" iyz="0.0" izz="1.0e-03" />
        </inertial>

    </link>
    <!-- end effector joint -->
    <joint name="end_effector_joint" type="fixed">
        <origin rpy="0 0 0" xyz="0.126 0.0 0.0" />
        <parent link="link5" />
        <child link="end_effector_link" />
    </joint>
    <!-- end effector link -->
    <link name="end_effector_link">
        <visual>
            <origin rpy="0 0 0" xyz="0 0 0" />
            <geometry>
                <box size="0.01 0.01 0.01" />
            </geometry>
            <material name="red" />
        </visual>
        
<inertial>
            <origin xyz="0 0 0" />
            <mass value="1.0e-03" />
            <inertia ixx="1.0e-03" ixy="0.0" ixz="0.0" iyy="1.0e-03" iyz="0.0" izz="1.0e-03" />
        </inertial>

    </link>
    <!-- Realsense Camera Joint Position
  <joint name="camera_joint" type="fixed">
    <axis xyz="0 1 0" />
    <origin xyz="0.070 0.032 0.052" rpy="0 0 0"/> 
    <parent link="link5"/>
    <child link="camera_link"/>
  </joint>

  <link name="camera_link"/> -->
    <!-- World -->
    <!-- <link name="world"/> -->
    <!-- World fixed joint-->
    <!-- <joint name="world_fixed" type="fixed">
    <origin xyz="0 0 0" rpy="0 0 0"/>
    <parent link="world"/>
    <child link="link1"/>
  </joint> -->
    <!-- World fixed joint-->
    <joint name="fix_world" type="fixed">
        <origin rpy="0 0 -1.57079632679" xyz="0.2 -0.08 0.14" />
        <parent link="base_footprint" />
        <child link="link1" />
    </joint>
    <!-- Link 1 -->
    <link name="workspace">
        <visual>
            <origin rpy="0 0 -1.57079632679" xyz="0.18 0.2 0" />
            <geometry>
                <mesh filename="package://openmanipulator_description/mesh/work_space.stl" scale="0.001 0.001 0.001" />
            </geometry>
            <material name="grey" />
        </visual>
        
<inertial>
            <origin xyz="3.0876154e-04 0.0000000e+00 -1.2176461e-04" />
            <mass value="7.9119962e-02" />
            <inertia ixx="1.2505234e-05" ixy="0.0" ixz="-1.7855208e-07" iyy="2.1898364e-05" iyz="0.0" izz="1.9267361e-05" />
        </inertial>

    </link>
    <joint name="workspace" type="fixed">
        <parent link="base_footprint" />
        <child link="workspace" />
        <origin rpy="0 0 0" xyz="0.0 0.0 0.0" />
        <axis xyz="0 0 1" />
    </joint>
    <joint name="pole_bottom_0_joint" type="fixed">
        <origin rpy="0 0 0" xyz="0.12 0.082 0.1028" />
        <parent link="base_link" />
        <child link="pole_bottom_0_link" />
    </joint>
    <link name="pole_bottom_0_link">
        <visual>
            <origin rpy="0 0 0" xyz="0 0 0" />
            <geometry>
                <mesh filename="package://turtlebot_description/meshes/stacks/hexagons/pole_bottom.dae" />
            </geometry>
        </visual>
        <collision>
            <origin rpy="0 0 0" xyz="0 0 0" />
            <geometry>
                <cylinder length="0.0492" radius="0.006" />
            </geometry>
        </collision>
        
<inertial>
            <mass value="0.008" />
            <origin rpy="0 0 0" xyz="0 0 0" />
            <inertia ixx="0.000001686" ixy="0.0" ixz="0.0" iyy="0.000001686" iyz="0.0" izz="0.000000144" />
        </inertial>

    </link>
    <joint name="pole_bottom_1_joint" type="fixed">
        <origin rpy="0 0 0" xyz="0.055 0.12 0.1028" />
        <parent link="base_link" />
        <child link="pole_bottom_1_link" />
    </joint>
    <link name="pole_bottom_1_link">
        <visual>
            <origin rpy="0 0 0" xyz="0 0 0" />
            <geometry>
                <mesh filename="package://turtlebot_description/meshes/stacks/hexagons/pole_bottom.dae" />
            </geometry>
        </visual>
        <collision>
            <origin rpy="0 0 0" xyz="0 0 0" />
            <geometry>
                <cylinder length="0.0492" radius="0.006" />
            </geometry>
        </collision>
        
<inertial>
            <mass value="0.008" />
            <origin rpy="0 0 0" xyz="0 0 0" />
            <inertia ixx="0.000001686" ixy="0.0" ixz="0.0" iyy="0.000001686" iyz="0.0" izz="0.000000144" />
        </inertial>

    </link>
    <joint name="pole_bottom_2_joint" type="fixed">
        <origin rpy="0 0 0" xyz="-0.055 0.12 0.1028" />
        <parent link="base_link" />
        <child link="pole_bottom_2_link" />
    </joint>
    <link name="pole_bottom_2_link">
        <visual>
            <origin rpy="0 0 0" xyz="0 0 0" />
            <geometry>
                <mesh filename="package://turtlebot_description/meshes/stacks/hexagons/pole_bottom.dae" />
            </geometry>
        </visual>
        <collision>
            <origin rpy="0 0 0" xyz="0 0 0" />
            <geometry>
                <cylinder length="0.0492" radius="0.006" />
            </geometry>
        </collision>
        
<inertial>
            <mass value="0.008" />
            <origin rpy="0 0 0" xyz="0 0 0" />
            <inertia ixx="0.000001686" ixy="0.0" ixz="0.0" iyy="0.000001686" iyz="0.0" izz="0.000000144" />
        </inertial>

    </link>
    <joint name="pole_bottom_3_joint" type="fixed">
        <origin rpy="0 0 0" xyz="0.12 -0.082 0.1028" />
        <parent link="base_link" />
        <child link="pole_bottom_3_link" />
    </joint>
    <link name="pole_bottom_3_link">
        <visual>
            <origin rpy="0 0 0" xyz="0 0 0" />
            <geometry>
                <mesh filename="package://turtlebot_description/meshes/stacks/hexagons/pole_bottom.dae" />
            </geometry>
        </visual>
        <collision>
            <origin rpy="0 0 0" xyz="0 0 0" />
            <geometry>
                <cylinder length="0.0492" radius="0.006" />
            </geometry>
        </collision>
        
<inertial>
            <mass value="0.008" />
            <origin rpy="0 0 0" xyz="0 0 0" />
            <inertia ixx="0.000001686" ixy="0.0" ixz="0.0" iyy="0.000001686" iyz="0.0" izz="0.000000144" />
        </inertial>

    </link>
    <joint name="pole_bottom_4_joint" type="fixed">
        <origin rpy="0 0 0" xyz="0.055 -0.12 0.1028" />
        <parent link="base_link" />
        <child link="pole_bottom_4_link" />
    </joint>
    <link name="pole_bottom_4_link">
        <visual>
            <origin rpy="0 0 0" xyz="0 0 0" />
            <geometry>
                <mesh filename="package://turtlebot_description/meshes/stacks/hexagons/pole_bottom.dae" />
            </geometry>
        </visual>
        <collision>
            <origin rpy="0 0 0" xyz="0 0 0" />
            <geometry>
                <cylinder length="0.0492" radius="0.006" />
            </geometry>
        </collision>
        
<inertial>
            <mass value="0.008" />
            <origin rpy="0 0 0" xyz="0 0 0" />
            <inertia ixx="0.000001686" ixy="0.0" ixz="0.0" iyy="0.000001686" iyz="0.0" izz="0.000000144" />
        </inertial>

    </link>
    <joint name="pole_bottom_5_joint" type="fixed">
        <origin rpy="0 0 0" xyz="-0.055 -0.12 0.1028" />
        <parent link="base_link" />
        <child link="pole_bottom_5_link" />
    </joint>
    <link name="pole_bottom_5_link">
        <visual>
            <origin rpy="0 0 0" xyz="0 0 0" />
            <geometry>
                <mesh filename="package://turtlebot_description/meshes/stacks/hexagons/pole_bottom.dae" />
            </geometry>
        </visual>
        <collision>
            <origin rpy="0 0 0" xyz="0 0 0" />
            <geometry>
                <cylinder length="0.0492" radius="0.006" />
            </geometry>
        </collision>
        
<inertial>
            <mass value="0.008" />
            <origin rpy="0 0 0" xyz="0 0 0" />
            <inertia ixx="0.000001686" ixy="0.0" ixz="0.0" iyy="0.000001686" iyz="0.0" izz="0.000000144" />
        </inertial>

    </link>
    <joint name="plate_bottom_joint" type="fixed">
        <origin rpy="0 0 0" xyz="0.02364 0.0 0.1306" />
        <parent link="base_link" />
        <child link="plate_bottom_link" />
    </joint>
    <link name="plate_bottom_link">
        <visual>
            <origin rpy="0 0 0" xyz="0 0 0" />
            <geometry>
                <mesh filename="package://turtlebot_description/meshes/stacks/hexagons/plate_bottom.dae" />
            </geometry>
        </visual>
        <collision>
            <origin rpy="0 0 0" xyz="-0.02364 0 0" />
            <geometry>
                <cylinder length="0.006" radius="0.170" />
            </geometry>
        </collision>
        
<inertial>
            <mass value="0.520" />
            <origin xyz="0 0 0" />
            <inertia ixx="0.003328" ixy="0.0" ixz="0.0" iyy="0.003328" iyz="0.0" izz="0.006656" />
        </inertial>

    </link>
    <joint name="pole_middle_0_joint" type="fixed">
        <origin rpy="0 0 0" xyz="0.0381 0.1505 0.164" />
        <parent link="base_link" />
        <child link="pole_middle_0_link" />
    </joint>
    <link name="pole_middle_0_link">
        <visual>
            <origin rpy="0 3.14159265359 0" xyz="0 0 0" />
            <geometry>
                <mesh filename="package://turtlebot_description/meshes/stacks/hexagons/pole_middle.dae" />
            </geometry>
        </visual>
        <collision>
            <origin rpy="0 0 0" xyz="0 0 0" />
            <geometry>
                <cylinder length="0.0608" radius="0.006" />
            </geometry>
        </collision>
        
<inertial>
            <mass value="0.012" />
            <origin xyz="0 0 0" />
            <inertia ixx="0.000003805" ixy="0.0" ixz="0.0" iyy="0.000003805" iyz="0.0" izz="0.000000216" />
        </inertial>

    </link>
    <joint name="pole_middle_1_joint" type="fixed">
        <origin rpy="0 0 0" xyz="0.0381 -0.1505 0.164" />
        <parent link="base_link" />
        <child link="pole_middle_1_link" />
    </joint>
    <link name="pole_middle_1_link">
        <visual>
            <origin rpy="0 3.14159265359 0" xyz="0 0 0" />
            <geometry>
                <mesh filename="package://turtlebot_description/meshes/stacks/hexagons/pole_middle.dae" />
            </geometry>
        </visual>
        <collision>
            <origin rpy="0 0 0" xyz="0 0 0" />
            <geometry>
                <cylinder length="0.0608" radius="0.006" />
            </geometry>
        </collision>
        
<inertial>
            <mass value="0.012" />
            <origin xyz="0 0 0" />
            <inertia ixx="0.000003805" ixy="0.0" ixz="0.0" iyy="0.000003805" iyz="0.0" izz="0.000000216" />
        </inertial>

    </link>
    <joint name="pole_middle_2_joint" type="fixed">
        <origin rpy="0 0 0" xyz="-0.0381 0.1505 0.164" />
        <parent link="base_link" />
        <child link="pole_middle_2_link" />
    </joint>
    <link name="pole_middle_2_link">
        <visual>
            <origin rpy="0 3.14159265359 0" xyz="0 0 0" />
            <geometry>
                <mesh filename="package://turtlebot_description/meshes/stacks/hexagons/pole_middle.dae" />
            </geometry>
        </visual>
        <collision>
            <origin rpy="0 0 0" xyz="0 0 0" />
            <geometry>
                <cylinder length="0.0608" radius="0.006" />
            </geometry>
        </collision>
        
<inertial>
            <mass value="0.012" />
            <origin xyz="0 0 0" />
            <inertia ixx="0.000003805" ixy="0.0" ixz="0.0" iyy="0.000003805" iyz="0.0" izz="0.000000216" />
        </inertial>

    </link>
    <joint name="pole_middle_3_joint" type="fixed">
        <origin rpy="0 0 0" xyz="-0.0381 -0.1505 0.164" />
        <parent link="base_link" />
        <child link="pole_middle_3_link" />
    </joint>
    <link name="pole_middle_3_link">
        <visual>
            <origin rpy="0 3.14159265359 0" xyz="0 0 0" />
            <geometry>
                <mesh filename="package://turtlebot_description/meshes/stacks/hexagons/pole_middle.dae" />
            </geometry>
        </visual>
        <collision>
            <origin rpy="0 0 0" xyz="0 0 0" />
            <geometry>
                <cylinder length="0.0608" radius="0.006" />
            </geometry>
        </collision>
        
<inertial>
            <mass value="0.012" />
            <origin xyz="0 0 0" />
            <inertia ixx="0.000003805" ixy="0.0" ixz="0.0" iyy="0.000003805" iyz="0.0" izz="0.000000216" />
        </inertial>

    </link>
    <joint name="plate_middle_joint" type="fixed">
        <origin rpy="0 0 0" xyz="-0.01364 0.0 0.1874" />
        <parent link="base_link" />
        <child link="plate_middle_link" />
    </joint>
    <link name="plate_middle_link">
        <visual>
            <origin rpy="0 0 0" xyz="0 0 0" />
            <geometry>
                <mesh filename="package://turtlebot_description/meshes/stacks/hexagons/plate_middle.dae" />
            </geometry>
        </visual>
        <collision>
            <origin rpy="0 0 0" xyz="0.01364 0.0 0.0" />
            <geometry>
                <cylinder length="0.006" radius="0.170" />
            </geometry>
        </collision>
        
<inertial>
            <mass value="0.520" />
            <origin xyz="0 0 0" />
            <inertia ixx="0.003328" ixy="0.0" ixz="0.0" iyy="0.003328" iyz="0.0" izz="0.006656" />
        </inertial>

    </link>
    <joint name="pole_top_0_joint" type="fixed">
        <origin rpy="0 0 0" xyz="0.0381 0.1505 0.292" />
        <parent link="base_link" />
        <child link="pole_top_0_link" />
    </joint>
    <link name="pole_top_0_link">
        <visual>
            <origin rpy="0 0 0" xyz=" 0 0 0" />
            <geometry>
                <mesh filename="package://turtlebot_description/meshes/stacks/hexagons/pole_top.dae" />
            </geometry>
        </visual>
        <collision>
            <origin rpy="0 0 0" xyz="0 0 0" />
            <geometry>
                <cylinder length="0.2032" radius="0.006" />
            </geometry>
        </collision>
        
<inertial>
            <mass value="0.060" />
            <origin xyz="0 0 0" />
            <inertia ixx="0.000206991" ixy="0.0" ixz="0.0" iyy="0.000206991" iyz="0.0" izz="0.000001080" />
        </inertial>

    </link>
    <joint name="pole_top_1_joint" type="fixed">
        <origin rpy="0 0 0" xyz="0.0381 -0.1505 0.292" />
        <parent link="base_link" />
        <child link="pole_top_1_link" />
    </joint>
    <link name="pole_top_1_link">
        <visual>
            <origin rpy="0 0 0" xyz=" 0 0 0" />
            <geometry>
                <mesh filename="package://turtlebot_description/meshes/stacks/hexagons/pole_top.dae" />
            </geometry>
        </visual>
        <collision>
            <origin rpy="0 0 0" xyz="0 0 0" />
            <geometry>
                <cylinder length="0.2032" radius="0.006" />
            </geometry>
        </collision>
        
<inertial>
            <mass value="0.060" />
            <origin xyz="0 0 0" />
            <inertia ixx="0.000206991" ixy="0.0" ixz="0.0" iyy="0.000206991" iyz="0.0" izz="0.000001080" />
        </inertial>

    </link>
    <joint name="pole_top_2_joint" type="fixed">
        <origin rpy="0 0 0" xyz="-0.0381 0.1505 0.292" />
        <parent link="base_link" />
        <child link="pole_top_2_link" />
    </joint>
    <link name="pole_top_2_link">
        <visual>
            <origin rpy="0 0 0" xyz=" 0 0 0" />
            <geometry>
                <mesh filename="package://turtlebot_description/meshes/stacks/hexagons/pole_top.dae" />
            </geometry>
        </visual>
        <collision>
            <origin rpy="0 0 0" xyz="0 0 0" />
            <geometry>
                <cylinder length="0.2032" radius="0.006" />
            </geometry>
        </collision>
        
<inertial>
            <mass value="0.060" />
            <origin xyz="0 0 0" />
            <inertia ixx="0.000206991" ixy="0.0" ixz="0.0" iyy="0.000206991" iyz="0.0" izz="0.000001080" />
        </inertial>

    </link>
    <joint name="pole_top_3_joint" type="fixed">
        <origin rpy="0 0 0" xyz="-0.0381 -0.1505 0.292" />
        <parent link="base_link" />
        <child link="pole_top_3_link" />
    </joint>
    <link name="pole_top_3_link">
        <visual>
            <origin rpy="0 0 0" xyz=" 0 0 0" />
            <geometry>
                <mesh filename="package://turtlebot_description/meshes/stacks/hexagons/pole_top.dae" />
            </geometry>
        </visual>
        <collision>
            <origin rpy="0 0 0" xyz="0 0 0" />
            <geometry>
                <cylinder length="0.2032" radius="0.006" />
            </geometry>
        </collision>
        
<inertial>
            <mass value="0.060" />
            <origin xyz="0 0 0" />
            <inertia ixx="0.000206991" ixy="0.0" ixz="0.0" iyy="0.000206991" iyz="0.0" izz="0.000001080" />
        </inertial>

    </link>
    <joint name="pole_kinect_0_joint" type="fixed">
        <origin rpy="0 0 0" xyz="-0.1024 0.098 0.2372" />
        <parent link="base_link" />
        <child link="pole_kinect_0_link" />
    </joint>
    <link name="pole_kinect_0_link">
        <visual>
            <origin rpy="0 0 0" xyz="0 0 -0.01" />
            <geometry>
                <mesh filename="package://turtlebot_description/meshes/sensors/sensor_pole.dae" />
            </geometry>
        </visual>
        <collision>
            <origin rpy="0 0 0" xyz="0 0 0" />
            <geometry>
                <cylinder length="0.0936" radius="0.006" />
            </geometry>
        </collision>
        
<inertial>
            <mass value="0.020" />
            <origin xyz="0 0 0" />
            <inertia ixx="0.000014782" ixy="0.0" ixz="0.0" iyy="0.000014782" iyz="0.0" izz="0.000000360" />
        </inertial>

    </link>
    <joint name="pole_kinect_1_joint" type="fixed">
        <origin rpy="0 0 0" xyz="-0.1024 -0.098 0.2372" />
        <parent link="base_link" />
        <child link="pole_kinect_1_link" />
    </joint>
    <link name="pole_kinect_1_link">
        <visual>
            <origin rpy="0 0 0" xyz="0 0 -0.01" />
            <geometry>
                <mesh filename="package://turtlebot_description/meshes/sensors/sensor_pole.dae" />
            </geometry>
        </visual>
        <collision>
            <origin rpy="0 0 0" xyz="0 0 0" />
            <geometry>
                <cylinder length="0.0936" radius="0.006" />
            </geometry>
        </collision>
        
<inertial>
            <mass value="0.020" />
            <origin xyz="0 0 0" />
            <inertia ixx="0.000014782" ixy="0.0" ixz="0.0" iyy="0.000014782" iyz="0.0" izz="0.000000360" />
        </inertial>

    </link>
    <joint name="plate_top_joint" type="fixed">
        <origin rpy="0 0 0" xyz="-0.01364 0.0  0.3966" />
        <parent link="base_link" />
        <child link="plate_top_link" />
    </joint>
    <link name="plate_top_link">
        <visual>
            <origin rpy="0 0 0" xyz="0 0 0" />
            <geometry>
                <mesh filename="package://turtlebot_description/meshes/stacks/hexagons/plate_top.dae" />
            </geometry>
        </visual>
        <collision>
            <origin rpy="0 0 0" xyz="0.01364 0 0" />
            <geometry>
                <cylinder length="0.006" radius="0.170" />
            </geometry>
        </collision>
        
<inertial>
            <mass value="0.520" />
            <origin xyz="0 0 0" />
            <inertia ixx="0.003328" ixy="0.0" ixz="0.0" iyy="0.003328" iyz="0.0" izz="0.006656" />
        </inertial>

    </link>
    <link name="base_footprint" />
    <!--
       Base link is set at the bottom of the base mould.
       This is done to be compatible with the way base link
       was configured for turtlebot 1. Refer to

       https://github.com/turtlebot/turtlebot/issues/40

       To put the base link at the more oft used wheel
       axis, set the z-distance from the base_footprint
       to 0.352.
      -->
    <joint name="base_joint" type="fixed">
        <origin rpy="0 0 0" xyz="0 0 0.0102" />
        <parent link="base_footprint" />
        <child link="base_link" />
    </joint>
    <link name="base_link">
        <visual>
            <geometry>
                <!-- new mesh -->
                <mesh filename="package://kobuki_description/meshes/main_body.dae" />
            </geometry>
            <origin rpy="0 0 0" xyz="0.001 0 0.05199" />
        </visual>
        <collision name="base">
            <geometry>
                <cylinder length="0.10938" radius="0.178" />
            </geometry>
            <origin rpy="0 0 0" xyz="0.0 0 0.05949" />
        </collision>
        
<inertial>
            <!-- COM experimentally determined -->
            <origin xyz="0.01 0 0" />
            <mass value="2.4" />
            <!-- 2.4/2.6 kg for small/big battery pack -->
            <!-- Kobuki's inertia tensor is approximated by a cylinder with homogeneous mass distribution
             More details: http://en.wikipedia.org/wiki/List_of_moment_of_inertia_tensors
             m = 2.4 kg; h = 0.09 m; r = 0.175 m
             ixx = 1/12 * m * (3 * r^2 + h^2)
             iyy = 1/12 * m * (3 * r^2 + h^2)
             izz = 1/2 * m * r^2
          -->
            <inertia ixx="0.019995" ixy="0.0" ixz="0.0" iyy="0.019995" iyz="0.0" izz="0.03675" />
        </inertial>

    </link>
    <joint name="wheel_left_joint" type="continuous">
        <parent link="base_link" />
        <child link="wheel_left_link" />
        <origin rpy="-1.57079632679 0 0" xyz="0.00 0.115 0.0250" />
        <axis xyz="0 0 1" />
    </joint>
    <link name="wheel_left_link">
        <visual>
            <geometry>
                <mesh filename="package://kobuki_description/meshes/wheel.dae" />
            </geometry>
            <origin rpy="0 0 0" xyz="0 0 0" />
        </visual>
        <collision>
            <geometry>
                <cylinder length="0.0206" radius="0.0352" />
            </geometry>
            <origin rpy="0 0 0" xyz="0 0 0" />
        </collision>
        
<inertial>
            <mass value="0.01" />
            <origin xyz="0 0 0" />
            <inertia ixx="0.001" ixy="0.0" ixz="0.0" iyy="0.001" iyz="0.0" izz="0.001" />
        </inertial>

    </link>
    <joint name="wheel_right_joint" type="continuous">
        <parent link="base_link" />
        <child link="wheel_right_link" />
        <origin rpy="-1.57079632679 0 0" xyz="0.00 -0.115 0.0250" />
        <axis xyz="0 0 1" />
    </joint>
    <link name="wheel_right_link">
        <visual>
            <geometry>
                <mesh filename="package://kobuki_description/meshes/wheel.dae" />
            </geometry>
            <origin rpy="0 0 0" xyz="0 0 0" />
        </visual>
        <collision>
            <geometry>
                <cylinder length="0.0206" radius="0.0350" />
            </geometry>
            <origin rpy="0 0 0" xyz="0 0 0" />
        </collision>
        
<inertial>
            <mass value="0.01" />
            <origin xyz="0 0 0" />
            <inertia ixx="0.001" ixy="0.0" ixz="0.0" iyy="0.001" iyz="0.0" izz="0.001" />
        </inertial>

    </link>
    <joint name="caster_front_joint" type="fixed">
        <parent link="base_link" />
        <child link="caster_front_link" />
        <origin rpy="-1.57079632679 0 0" xyz="0.115 0.0 0.007" />
    </joint>
    <link name="caster_front_link">
        <collision>
            <geometry>
                <cylinder length="0.0176" radius="0.017" />
            </geometry>
            <origin rpy="0 0 0" xyz="0 0 0" />
        </collision>
        
<inertial>
            <mass value="0.01" />
            <origin xyz="0 0 0" />
            <inertia ixx="0.001" ixy="0.0" ixz="0.0" iyy="0.001" iyz="0.0" izz="0.001" />
        </inertial>

    </link>
    <joint name="caster_back_joint" type="fixed">
        <parent link="base_link" />
        <child link="caster_back_link" />
        <origin rpy="-1.57079632679 0 0" xyz="-0.135 0.0 0.009" />
    </joint>
    <link name="caster_back_link">
        <collision>
            <geometry>
                <cylinder length="0.0176" radius="0.017" />
            </geometry>
            <origin rpy="0 0 0" xyz="0 0 0" />
        </collision>
        
<inertial>
            <mass value="0.01" />
            <origin xyz="0 0 0" />
            <inertia ixx="0.001" ixy="0.0" ixz="0.0" iyy="0.001" iyz="0.0" izz="0.001" />
        </inertial>

    </link>
    <!-- Kobuki's sensors -->
    <joint name="gyro_joint" type="fixed">
        <axis xyz="0 1 0" />
        <origin rpy="0 0 0" xyz="0.056 0.062 0.0202" />
        <parent link="base_link" />
        <child link="gyro_link" />
    </joint>
    <link name="gyro_link">
        
<inertial>
            <mass value="0.001" />
            <origin rpy="0 0 0" xyz="0 0 0" />
            <inertia ixx="0.0001" ixy="0" ixz="0" iyy="0.000001" iyz="0" izz="0.0001" />
        </inertial>

    </link>
    <joint name="cliff_sensor_left_joint" type="fixed">
        <origin rpy="0 1.57079632679 0" xyz="0.08734 0.13601 0.0214" />
        <parent link="base_link" />
        <child link="cliff_sensor_left_link" />
    </joint>
    <link name="cliff_sensor_left_link">
        
<inertial>
            <mass value="0.0001" />
            <origin xyz="0 0 0" />
            <inertia ixx="0.0001" ixy="0.0" ixz="0.0" iyy="0.0001" iyz="0.0" izz="0.0001" />
        </inertial>

    </link>
    <joint name="cliff_sensor_right_joint" type="fixed">
        <origin rpy="0 1.57079632679 0" xyz="0.085 -0.13601 0.0214" />
        <parent link="base_link" />
        <child link="cliff_sensor_right_link" />
    </joint>
    <link name="cliff_sensor_right_link">
        
<inertial>
            <mass value="0.0001" />
            <origin xyz="0 0 0" />
            <inertia ixx="0.0001" ixy="0.0" ixz="0.0" iyy="0.0001" iyz="0.0" izz="0.0001" />
        </inertial>

    </link>
    <joint name="cliff_sensor_front_joint" type="fixed">
        <origin rpy="0 1.57079632679 0" xyz="0.156 0.00 0.0214" />
        <parent link="base_link" />
        <child link="cliff_sensor_front_link" />
    </joint>
    <link name="cliff_sensor_front_link">
        
<inertial>
            <mass value="0.0001" />
            <origin xyz="0 0 0" />
            <inertia ixx="0.0001" ixy="0.0" ixz="0.0" iyy="0.0001" iyz="0.0" izz="0.0001" />
        </inertial>

    </link>
    <gazebo reference="wheel_left_link">
        <mu1>1.0</mu1>
        <mu2>1.0</mu2>
        <kp>1000000.0</kp>
        <kd>100.0</kd>
        <minDepth>0.001</minDepth>
        <maxVel>1.0</maxVel>
    </gazebo>
    <gazebo reference="wheel_right_link">
        <mu1>1.0</mu1>
        <mu2>1.0</mu2>
        <kp>1000000.0</kp>
        <kd>100.0</kd>
        <minDepth>0.001</minDepth>
        <maxVel>1.0</maxVel>
    </gazebo>
    <gazebo reference="caster_front_link">
        <mu1>0.0</mu1>
        <mu2>0.0</mu2>
        <kp>1000000.0</kp>
        <kd>100.0</kd>
        <minDepth>0.001</minDepth>
        <maxVel>1.0</maxVel>
    </gazebo>
    <gazebo reference="caster_back_link">
        <mu1>0.0</mu1>
        <mu2>0.0</mu2>
        <kp>1000000.0</kp>
        <kd>100.0</kd>
        <minDepth>0.001</minDepth>
        <maxVel>1.0</maxVel>
    </gazebo>
    <gazebo reference="base_link">
        <mu1>0.3</mu1>
        <mu2>0.3</mu2>
        <sensor name="bumpers" type="contact">
            <always_on>1</always_on>
            <update_rate>50.0</update_rate>
            <visualize>true</visualize>
            <contact>
                <collision>base_footprint_fixed_joint_lump__base_collision</collision>
            </contact>
        </sensor>
    </gazebo>
    <gazebo reference="cliff_sensor_left_link">
        <sensor name="cliff_sensor_left" type="ray">
            <always_on>true</always_on>
            <update_rate>50</update_rate>
            <visualize>true</visualize>
            <ray>
                <scan>
                    <horizontal>
                        <samples>50</samples>
                        <resolution>1.0</resolution>
                        <min_angle>-0.0436</min_angle>
                        <!-- -2.5 degree -->
                        <max_angle>0.0436</max_angle>
                        <!-- 2.5 degree -->
                    </horizontal>
                    <!--            Can't use vertical rays until this bug is resolved: -->
                    <!--            https://bitbucket.org/osrf/gazebo/issue/509/vertical-sensor-doesnt-works -->
                    <!-- 	          <vertical> -->
                    <!-- 	            <samples>50</samples> -->
                    <!-- 	            <resolution>1.0</resolution> -->
                    <!-- 	            <min_angle>-0.0436</min_angle>  -2.5 degree -->
                    <!-- 	            <max_angle>0.0436</max_angle> 2.5 degree -->
                    <!-- 	          </vertical> -->
                </scan>
                <range>
                    <min>0.01</min>
                    <max>0.15</max>
                    <resolution>1.0</resolution>
                </range>
            </ray>
        </sensor>
    </gazebo>
    <gazebo reference="cliff_sensor_right_link">
        <sensor name="cliff_sensor_right" type="ray">
            <always_on>true</always_on>
            <update_rate>50</update_rate>
            <visualize>true</visualize>
            <ray>
                <scan>
                    <horizontal>
                        <samples>50</samples>
                        <resolution>1.0</resolution>
                        <min_angle>-0.0436</min_angle>
                        <!-- -2.5 degree -->
                        <max_angle>0.0436</max_angle>
                        <!-- 2.5 degree -->
                    </horizontal>
                    <!--            Can't use vertical rays until this bug is resolved: -->
                    <!--            https://bitbucket.org/osrf/gazebo/issue/509/vertical-sensor-doesnt-works -->
                    <!-- 	          <vertical> -->
                    <!-- 	            <samples>50</samples> -->
                    <!-- 	            <resolution>1.0</resolution> -->
                    <!-- 	            <min_angle>-0.0436</min_angle>  -2.5 degree -->
                    <!-- 	            <max_angle>0.0436</max_angle> 2.5 degree -->
                    <!-- 	          </vertical> -->
                </scan>
                <range>
                    <min>0.01</min>
                    <max>0.15</max>
                    <resolution>1.0</resolution>
                </range>
            </ray>
        </sensor>
    </gazebo>
    <gazebo reference="cliff_sensor_front_link">
        <sensor name="cliff_sensor_front" type="ray">
            <always_on>true</always_on>
            <update_rate>50</update_rate>
            <visualize>true</visualize>
            <ray>
                <scan>
                    <horizontal>
                        <samples>50</samples>
                        <resolution>1.0</resolution>
                        <min_angle>-0.0436</min_angle>
                        <!-- -2.5 degree -->
                        <max_angle>0.0436</max_angle>
                        <!-- 2.5 degree -->
                    </horizontal>
                    <!-- 	          Can't use vertical rays until this bug is resolved: -->
                    <!--            https://bitbucket.org/osrf/gazebo/issue/509/vertical-sensor-doesnt-works -->
                    <!-- 	          <vertical> -->
                    <!-- 	            <samples>50</samples> -->
                    <!-- 	            <resolution>1.0</resolution> -->
                    <!-- 	            <min_angle>-0.0436</min_angle>  -2.5 degree -->
                    <!-- 	            <max_angle>0.0436</max_angle> 2.5 degree -->
                    <!-- 	          </vertical> -->
                </scan>
                <range>
                    <min>0.01</min>
                    <max>0.15</max>
                    <resolution>1.0</resolution>
                </range>
            </ray>
        </sensor>
    </gazebo>
    <gazebo reference="gyro_link">
        <sensor name="imu" type="imu">
            <always_on>true</always_on>
            <update_rate>50</update_rate>
            <visualize>false</visualize>
            <imu>
                <noise>
                    <type>gaussian</type>
                    <rate>
                        <mean>0.0</mean>
                        <stddev>1.96e-06</stddev>
                        <!-- 0.25 x 0.25 (deg/s) -->
                        <bias_mean>0.0</bias_mean>
                        <bias_stddev>0.0</bias_stddev>
                    </rate>
                    <accel>
                        <!-- not used in the plugin and real robot, hence using tutorial values -->
                        <mean>0.0</mean>
                        <stddev>1.7e-2</stddev>
                        <bias_mean>0.1</bias_mean>
                        <bias_stddev>0.001</bias_stddev>
                    </accel>
                </noise>
            </imu>
        </sensor>
    </gazebo>
    <gazebo>
        <plugin filename="libgazebo_ros_kobuki.so" name="kobuki_controller">
            <publish_tf>1</publish_tf>
            <left_wheel_joint_name>wheel_left_joint</left_wheel_joint_name>
            <right_wheel_joint_name>wheel_right_joint</right_wheel_joint_name>
            <wheel_separation>.230</wheel_separation>
            <wheel_diameter>0.070</wheel_diameter>
            <torque>1.0</torque>
            <velocity_command_timeout>0.6</velocity_command_timeout>
            <cliff_sensor_left_name>cliff_sensor_left</cliff_sensor_left_name>
            <cliff_sensor_center_name>cliff_sensor_front</cliff_sensor_center_name>
            <cliff_sensor_right_name>cliff_sensor_right</cliff_sensor_right_name>
            <cliff_detection_threshold>0.04</cliff_detection_threshold>
            <bumper_name>bumpers</bumper_name>
            <imu_name>imu</imu_name>
        </plugin>
    </gazebo>
    <!-- <link name="kinect_adjust_link"/>
  <joint name="kinect_adjust" type="floating">
    <origin xyz="0 0 0" rpy="0 0 0"/>
    <parent link="base_footprint"/>
    <child link="kinect_adjust_link"/>
    <limit effort="10" lower="-0.2" upper="0.2"/>
  </joint> -->
    <joint name="camera_rgb_joint" type="fixed">
        <origin rpy="3.14 0.475 0" xyz="0.03 -0.0125 0.3" />
        <parent link="base_footprint" />
        <child link="camera_rgb_frame" />
    </joint>
    <link name="camera_rgb_frame" />
    <joint name="camera_rgb_optical_joint" type="fixed">
        <origin rpy="-1.57079632679 0 -1.57079632679" xyz="0 0 0" />
        <parent link="camera_rgb_frame" />
        <child link="camera_rgb_optical_frame" />
    </joint>
    <link name="camera_rgb_optical_frame" />
    <joint name="camera_joint" type="fixed">
        <origin rpy="0 0 0" xyz="-0.031 0.0125 -0.016" />
        <parent link="camera_rgb_frame" />
        <child link="camera_link" />
    </joint>
    <link name="camera_link">
        <visual>
            <origin rpy="0 0 1.57079632679" xyz="0 0 0" />
            <geometry>
                <mesh filename="package://turtlebot_description/meshes/sensors/kinect.dae" />
            </geometry>
        </visual>
        <collision>
            <origin rpy="0 0 0" xyz="0.0 0.0 0.0" />
            <geometry>
                <box size="0.07271 0.27794 0.073" />
            </geometry>
        </collision>
        
<inertial>
            <mass value="0.564" />
            <origin xyz="0 0 0" />
            <inertia ixx="0.003881243" ixy="0.0" ixz="0.0" iyy="0.000498940" iyz="0.0" izz="0.003879257" />
        </inertial>

    </link>
    <!-- The fixed joints & links below are usually published by static_transformers launched by the OpenNi launch 
         files. However, for Gazebo simulation we need them, so we add them here.
         (Hence, don't publish them additionally!) -->
    <joint name="camera_depth_joint" type="fixed">
        <origin rpy="0 0 0" xyz="0 0.025 0" />
        <parent link="camera_rgb_frame" />
        <child link="camera_depth_frame" />
    </joint>
    <link name="camera_depth_frame" />
    <joint name="camera_depth_optical_joint" type="fixed">
        <origin rpy="-1.57079632679 0 -1.57079632679" xyz="0 0 0" />
        <parent link="camera_depth_frame" />
        <child link="camera_depth_optical_frame" />
    </joint>
    <link name="camera_depth_optical_frame" />
    <gazebo reference="camera_link">
        <sensor name="camera" type="depth">
            <always_on>true</always_on>
            <update_rate>20.0</update_rate>
            <camera>
                <horizontal_fov>1.0471975512</horizontal_fov>
                <image>
                    <format>B8G8R8</format>
                    <width>640</width>
                    <height>480</height>
                </image>
                <clip>
                    <near>0.05</near>
                    <far>8.0</far>
                </clip>
            </camera>
            <plugin filename="libgazebo_ros_openni_kinect.so" name="kinect_camera_controller">
                <cameraName>camera</cameraName>
                <alwaysOn>true</alwaysOn>
                <updateRate>10</updateRate>
                <imageTopicName>rgb/image_raw</imageTopicName>
                <depthImageTopicName>depth/image_raw</depthImageTopicName>
                <pointCloudTopicName>depth/points</pointCloudTopicName>
                <cameraInfoTopicName>rgb/camera_info</cameraInfoTopicName>
                <depthImageCameraInfoTopicName>depth/camera_info</depthImageCameraInfoTopicName>
                <frameName>camera_depth_optical_frame</frameName>
                <baseline>0.1</baseline>
                <distortion_k1>0.0</distortion_k1>
                <distortion_k2>0.0</distortion_k2>
                <distortion_k3>0.0</distortion_k3>
                <distortion_t1>0.0</distortion_t1>
                <distortion_t2>0.0</distortion_t2>
                <pointCloudCutoff>0.4</pointCloudCutoff>
            </plugin>
        </sensor>
    </gazebo>
    <link name="laser">
        <collision>
            <origin rpy="0 0 0" xyz="0 0 0" />
            <geometry>
                <box size="0.1 0.1 0.1" />
            </geometry>
        </collision>
        <visual>
            <origin rpy="0 0 0" xyz="0 0 0" />
            <geometry>
                <mesh filename="package://lidar_description/mesh/hokuyo.dae" />
            </geometry>
        </visual>
        
<inertial>
            <mass value="1e-5" />
            <origin rpy="0 0 0" xyz="0 0 0" />
            <inertia ixx="1e-6" ixy="0" ixz="0" iyy="1e-6" iyz="0" izz="1e-6" />
        </inertial>

    </link>
    <joint name="hokuyo_joint" type="fixed">
        <axis xyz="0 0 1" />
        <origin rpy="0 0 0" xyz="0 0 0.035" />
        <parent link="plate_top_link" />
        <child link="laser" />
    </joint>
    <transmission name="trans_joint1">
        <type>transmission_interface/SimpleTransmission</type>
        <joint name="joint1">
            <hardwareInterface>hardware_interface/EffortJointInterface</hardwareInterface>
        </joint>
        <actuator name="joint1_motor">
            <hardwareInterface>hardware_interface/EffortJointInterface</hardwareInterface>
            <mechanicalReduction>1</mechanicalReduction>
        </actuator>
    </transmission>
    <transmission name="trans_joint2">
        <type>transmission_interface/SimpleTransmission</type>
        <joint name="joint2">
            <hardwareInterface>hardware_interface/EffortJointInterface</hardwareInterface>
        </joint>
        <actuator name="joint2_motor">
            <hardwareInterface>hardware_interface/EffortJointInterface</hardwareInterface>
            <mechanicalReduction>1</mechanicalReduction>
        </actuator>
    </transmission>
    <transmission name="trans_joint3">
        <type>transmission_interface/SimpleTransmission</type>
        <joint name="joint3">
            <hardwareInterface>hardware_interface/EffortJointInterface</hardwareInterface>
        </joint>
        <actuator name="joint3_motor">
            <hardwareInterface>hardware_interface/EffortJointInterface</hardwareInterface>
            <mechanicalReduction>1</mechanicalReduction>
        </actuator>
    </transmission>
    <transmission name="trans_joint4">
        <type>transmission_interface/SimpleTransmission</type>
        <joint name="joint4">
            <hardwareInterface>hardware_interface/EffortJointInterface</hardwareInterface>
        </joint>
        <actuator name="joint4_motor">
            <hardwareInterface>hardware_interface/EffortJointInterface</hardwareInterface>
            <mechanicalReduction>1</mechanicalReduction>
        </actuator>
    </transmission>
    <transmission name="trans_gripper">
        <type>transmission_interface/SimpleTransmission</type>
        <joint name="gripper">
            <hardwareInterface>hardware_interface/EffortJointInterface</hardwareInterface>
        </joint>
        <actuator name="gripper_motor">
            <hardwareInterface>hardware_interface/EffortJointInterface</hardwareInterface>
            <mechanicalReduction>1</mechanicalReduction>
        </actuator>
    </transmission>
    <transmission name="trans_gripper_sub">
        <type>transmission_interface/SimpleTransmission</type>
        <joint name="gripper_sub">
            <hardwareInterface>hardware_interface/EffortJointInterface</hardwareInterface>
        </joint>
        <actuator name="gripper_sub_motor">
            <hardwareInterface>hardware_interface/EffortJointInterface</hardwareInterface>
            <mechanicalReduction>1</mechanicalReduction>
        </actuator>
    </transmission>
    <transmission name="trans_wheel_left_joint">
        <type>transmission_interface/SimpleTransmission</type>
        <joint name="wheel_left_joint">
            <hardwareInterface>hardware_interface/EffortJointInterface</hardwareInterface>
        </joint>
        <actuator name="wheel_left_joint_motor">
            <hardwareInterface>hardware_interface/EffortJointInterface</hardwareInterface>
            <mechanicalReduction>1</mechanicalReduction>
        </actuator>
    </transmission>
    <transmission name="trans_wheel_right_joint">
        <type>transmission_interface/SimpleTransmission</type>
        <joint name="wheel_right_joint">
            <hardwareInterface>hardware_interface/EffortJointInterface</hardwareInterface>
        </joint>
        <actuator name="wheel_right_joint_motor">
            <hardwareInterface>hardware_interface/EffortJointInterface</hardwareInterface>
            <mechanicalReduction>1</mechanicalReduction>
        </actuator>
    </transmission>
    <gazebo>
        <plugin name="gazebo_ros_control" filename="libgazebo_ros_control.so">
            <robotNamespace>/</robotNamespace>
        </plugin>
    </gazebo>
</robot>

<transmission name="tran1">
        <type>transmission_interface/SimpleTransmission</type>
        <joint name="joint1">
            <hardwareInterface>hardware_interface/PositionJointInterface</hardwareInterface>
        </joint>
        <actuator name="motor1">
            <mechanicalReduction>1</mechanicalReduction>
        </actuator>
    </transmission>
    <transmission name="tran2">
        <type>transmission_interface/SimpleTransmission</type>
        <joint name="joint2">
            <hardwareInterface>hardware_interface/PositionJointInterface</hardwareInterface>
        </joint>
        <actuator name="motor2">
            <mechanicalReduction>1</mechanicalReduction>
        </actuator>
    </transmission>
    <transmission name="tran3">
        <type>transmission_interface/SimpleTransmission</type>
        <joint name="joint3">
            <hardwareInterface>hardware_interface/PositionJointInterface</hardwareInterface>
        </joint>
        <actuator name="motor3">
            <mechanicalReduction>1</mechanicalReduction>
        </actuator>
    </transmission>
    <transmission name="tran4">
        <type>transmission_interface/SimpleTransmission</type>
        <joint name="joint4">
            <hardwareInterface>hardware_interface/PositionJointInterface</hardwareInterface>
        </joint>
        <actuator name="motor4">
            <mechanicalReduction>1</mechanicalReduction>
        </actuator>
    </transmission>
    <transmission name="tran5">
        <type>transmission_interface/SimpleTransmission</type>
        <joint name="gripper">
            <hardwareInterface>hardware_interface/EffortJointInterface</hardwareInterface>
        </joint>
        <actuator name="motor5">
            <mechanicalReduction>1</mechanicalReduction>
        </actuator>
    </transmission>
    <transmission name="tran6">
        <type>transmission_interface/SimpleTransmission</type>
        <joint name="gripper_sub">
            <hardwareInterface>hardware_interface/EffortJointInterface</hardwareInterface>
        </joint>
        <actuator name="motor6">
            <mechanicalReduction>1</mechanicalReduction>
        </actuator>
    </transmission>
    <!-- Link 1 -->
    <link name="link1">
        <visual>
            <origin rpy="0 0 0" xyz="0 0 0" />
            <geometry>
                <mesh filename="package://open_manipulator_description/meshes/chain_link1.stl" scale="0.001 0.001 0.001" />
            </geometry>
            <material name="grey" />
        </visual>
        <collision>
            <origin rpy="0 0 0" xyz="0 0 0" />
            <geometry>
                <mesh filename="package://open_manipulator_description/meshes/chain_link1.stl" scale="0.001 0.001 0.001" />
            </geometry>
        </collision>
        <inertial>
            <origin xyz="3.0876154e-04 0.0000000e+00 -1.2176461e-04" />
            <mass value="7.9119962e-02" />
            <inertia ixx="1.2505234e-05" ixy="0.0" ixz="-1.7855208e-07" iyy="2.1898364e-05" iyz="0.0" izz="1.9267361e-05" />
        </inertial>
    </link>
    <!-- Joint 1 -->
    <joint name="joint1" type="revolute">
        <parent link="link1" />
        <child link="link2" />
        <origin rpy="0 0 0" xyz="0.012 0.0 0.017" />
        <axis xyz="0 0 1" />
        <limit effort="1" lower="-2.82743338823" upper="2.82743338823" velocity="4.8" />
    </joint>
    <!--  Link 2 -->
    <link name="link2">
        <visual>
            <origin rpy="0 0 0" xyz="0 0 0.019" />
            <geometry>
                <mesh filename="package://open_manipulator_description/meshes/chain_link2.stl" scale="0.001 0.001 0.001" />
            </geometry>
            <material name="grey" />
        </visual>
        <collision>
            <origin rpy="0 0 0" xyz="0 0 0.019" />
            <geometry>
                <mesh filename="package://open_manipulator_description/meshes/chain_link2.stl" scale="0.001 0.001 0.001" />
            </geometry>
        </collision>
        <inertial>
            <origin xyz="-3.0184870e-04 5.4043684e-04 0.047433464" />
            <mass value="9.8406837e-02" />
            <inertia ixx="3.4543422e-05" ixy="-1.6031095e-08" ixz="-3.8375155e-07" iyy="3.2689329e-05" iyz="2.8511935e-08" izz="1.8850320e-05" />
        </inertial>
    </link>
    <!--  Joint 2 -->
    <joint name="joint2" type="revolute">
        <parent link="link2" />
        <child link="link3" />
        <origin rpy="0 0 0" xyz="0.0 0.0 0.0595" />
        <axis xyz="0 1 0" />
        <limit effort="1" lower="-1.79070781255" upper="1.57079632679" velocity="4.8" />
    </joint>
    <!--  Link 3 -->
    <link name="link3">
        <visual>
            <origin rpy="0 0 0" xyz="0 0 0" />
            <geometry>
                <mesh filename="package://open_manipulator_description/meshes/chain_link3.stl" scale="0.001 0.001 0.001" />
            </geometry>
            <material name="grey" />
        </visual>
        <collision>
            <origin rpy="0 0 0" xyz="0 0 0" />
            <geometry>
                <mesh filename="package://open_manipulator_description/meshes/chain_link3.stl" scale="0.001 0.001 0.001" />
            </geometry>
        </collision>
        <inertial>
            <origin xyz="1.0308393e-02 3.7743363e-04 1.0170197e-01" />
            <mass value="1.3850917e-01" />
            <inertia ixx="3.3055381e-04" ixy="-9.7940978e-08" ixz="-3.8505711e-05" iyy="3.4290447e-04" iyz="-1.5717516e-06" izz="6.0346498e-05" />
        </inertial>
    </link>
    <!--  Joint 3 -->
    <joint name="joint3" type="revolute">
        <parent link="link3" />
        <child link="link4" />
        <origin rpy="0 0 0" xyz="0.024 0 0.128" />
        <axis xyz="0 1 0" />
        <limit effort="1" lower="-0.942477796077" upper="1.38230076758" velocity="4.8" />
    </joint>
    <!--  Link 4 -->
    <link name="link4">
        <visual>
            <origin rpy="0 0 0" xyz="0 0 0" />
            <geometry>
                <mesh filename="package://open_manipulator_description/meshes/chain_link4.stl" scale="0.001 0.001 0.001" />
            </geometry>
            <material name="grey" />
        </visual>
        <collision>
            <origin rpy="0 0 0" xyz="0 0 0" />
            <geometry>
                <mesh filename="package://open_manipulator_description/meshes/chain_link4.stl" scale="0.001 0.001 0.001" />
            </geometry>
        </collision>
        <inertial>
            <origin xyz="9.0909590e-02 3.8929816e-04 2.2413279e-04" />
            <mass value="1.3274562e-01" />
            <inertia ixx="3.0654178e-05" ixy="-1.2764155e-06" ixz="-2.6874417e-07" iyy="2.4230292e-04" iyz="1.1559550e-08" izz="2.5155057e-04" />
        </inertial>
    </link>
    <!--  Joint 4 -->
    <joint name="joint4" type="revolute">
        <parent link="link4" />
        <child link="link5" />
        <origin rpy="0 0 0" xyz="0.124 0.0 0.0" />
        <axis xyz="0 1 0" />
        <limit effort="1" lower="-1.79070781255" upper="2.04203522483" velocity="4.8" />
    </joint>
    <!--  Link 5 -->
    <link name="link5">
        <visual>
            <origin rpy="0 0 0" xyz="0 0 0" />
            <geometry>
                <mesh filename="package://open_manipulator_description/meshes/chain_link5.stl" scale="0.001 0.001 0.001" />
            </geometry>
            <material name="grey" />
        </visual>
        <collision>
            <origin rpy="0 0 0" xyz="0 0 0" />
            <geometry>
                <mesh filename="package://open_manipulator_description/meshes/chain_link5.stl" scale="0.001 0.001 0.001" />
            </geometry>
        </collision>
        <inertial>
            <origin xyz="4.4206755e-02 3.6839985e-07 8.9142216e-03" />
            <mass value="1.4327573e-01" />
            <inertia ixx="8.0870749e-05" ixy="0.0" ixz="-1.0157896e-06" iyy="7.5980465e-05" iyz="0.0" izz="9.3127351e-05" />
        </inertial>
    </link>
    <!--  Gripper joint -->
    <joint name="gripper" type="prismatic">
        <parent link="link5" />
        <child link="gripper_link" />
        <origin rpy="0 0 0" xyz="0.0817 0.021 0.0" />
        <axis xyz="0 1 0" />
        <limit effort="1" lower="-0.010" upper="0.019" velocity="4.8" />
    </joint>
    <!--  Gripper link -->
    <link name="gripper_link">
        <visual>
            <origin rpy="0 0 0" xyz="0.0 0.0 0" />
            <geometry>
                <mesh filename="package://open_manipulator_description/meshes/chain_link_grip_l.stl" scale="0.001 0.001 0.001" />
            </geometry>
            <material name="grey" />
        </visual>
        <collision>
            <origin rpy="0 0 0" xyz="0.0 0.0 0" />
            <geometry>
                <mesh filename="package://open_manipulator_description/meshes/chain_link_grip_l.stl" scale="0.001 0.001 0.001" />
            </geometry>
        </collision>
        <inertial>
            <origin xyz="0 0 0" />
            <mass value="1.0e-03" />
            <inertia ixx="1.0e-03" ixy="0.0" ixz="0.0" iyy="1.0e-03" iyz="0.0" izz="1.0e-03" />
        </inertial>
    </link>
    <!--  Gripper joint sub -->
    <joint name="gripper_sub" type="prismatic">
        <parent link="link5" />
        <child link="gripper_link_sub" />
        <origin rpy="0 0 0" xyz="0.0817 -0.021 0" />
        <axis xyz="0 -1 0" />
        <limit effort="1" lower="-0.010" upper="0.019" velocity="4.8" />
        <mimic joint="gripper" multiplier="1" />
    </joint>
    <!--  Gripper link sub -->
    <link name="gripper_link_sub">
        <visual>
            <origin rpy="0 0 0" xyz="0.0 -0.0 0" />
            <geometry>
                <mesh filename="package://open_manipulator_description/meshes/chain_link_grip_r.stl" scale="0.001 0.001 0.001" />
            </geometry>
            <material name="grey" />
        </visual>
        <collision>
            <origin rpy="0 0 0" xyz="0.0 -0.0 0" />
            <geometry>
                <mesh filename="package://open_manipulator_description/meshes/chain_link_grip_r.stl" scale="0.001 0.001 0.001" />
            </geometry>
        </collision>
        <inertial>
            <origin xyz="0 0 0" />
            <mass value="1.0e-03" />
            <inertia ixx="1.0e-03" ixy="0.0" ixz="0.0" iyy="1.0e-03" iyz="0.0" izz="1.0e-03" />
        </inertial>
    </link>
    <!-- end effector joint -->
    <joint name="end_effector_joint" type="fixed">
        <origin rpy="0 0 0" xyz="0.126 0.0 0.0" />
        <parent link="link5" />
        <child link="end_effector_link" />
    </joint>
    <!-- end effector link -->
    <link name="end_effector_link">
        <visual>
            <origin rpy="0 0 0" xyz="0 0 0" />
            <geometry>
                <box size="0.01 0.01 0.01" />
            </geometry>
            <material name="red" />
        </visual>
        <inertial>
            <origin xyz="0 0 0" />
            <mass value="1.0e-03" />
            <inertia ixx="1.0e-03" ixy="0.0" ixz="0.0" iyy="1.0e-03" iyz="0.0" izz="1.0e-03" />
        </inertial>
    </link>
    <!-- Realsense Camera Joint Position
  <joint name="camera_joint" type="fixed">
    <axis xyz="0 1 0" />
    <origin xyz="0.070 0.032 0.052" rpy="0 0 0"/> 
    <parent link="link5"/>
    <child link="camera_link"/>
  </joint>

  <link name="camera_link"/> -->
    <!-- World -->
    <!-- <link name="world"/> -->
    <!-- World fixed joint-->
    <!-- <joint name="world_fixed" type="fixed">
    <origin xyz="0 0 0" rpy="0 0 0"/>
    <parent link="world"/>
    <child link="link1"/>
  </joint> -->
    <!-- World fixed joint-->
    <joint name="fix_world" type="fixed">
        <origin rpy="0 0 -1.57079632679" xyz="0.2 -0.08 0.14" />
        <parent link="base_footprint" />
        <child link="link1" />
    </joint>
    <!-- Link 1 -->
    <link name="workspace">
        <visual>
            <origin rpy="0 0 -1.57079632679" xyz="0.18 0.2 0" />
            <geometry>
                <mesh filename="package://openmanipulator_description/mesh/work_space.stl" scale="0.001 0.001 0.001" />
            </geometry>
            <material name="grey" />
        </visual>
        <inertial>
            <origin xyz="3.0876154e-04 0.0000000e+00 -1.2176461e-04" />
            <mass value="7.9119962e-02" />
            <inertia ixx="1.2505234e-05" ixy="0.0" ixz="-1.7855208e-07" iyy="2.1898364e-05" iyz="0.0" izz="1.9267361e-05" />
        </inertial>
    </link>
    <joint name="workspace" type="fixed">
        <parent link="base_footprint" />
        <child link="workspace" />
        <origin rpy="0 0 0" xyz="0.0 0.0 0.0" />
        <axis xyz="0 0 1" />
    </joint>
    <joint name="pole_bottom_0_joint" type="fixed">
        <origin rpy="0 0 0" xyz="0.12 0.082 0.1028" />
        <parent link="base_link" />
        <child link="pole_bottom_0_link" />
    </joint>
    <link name="pole_bottom_0_link">
        <visual>
            <origin rpy="0 0 0" xyz="0 0 0" />
            <geometry>
                <mesh filename="package://turtlebot_description/meshes/stacks/hexagons/pole_bottom.dae" />
            </geometry>
        </visual>
        <collision>
            <origin rpy="0 0 0" xyz="0 0 0" />
            <geometry>
                <cylinder length="0.0492" radius="0.006" />
            </geometry>
        </collision>
        <inertial>
            <mass value="0.008" />
            <origin rpy="0 0 0" xyz="0 0 0" />
            <inertia ixx="0.000001686" ixy="0.0" ixz="0.0" iyy="0.000001686" iyz="0.0" izz="0.000000144" />
        </inertial>
    </link>
    <joint name="pole_bottom_1_joint" type="fixed">
        <origin rpy="0 0 0" xyz="0.055 0.12 0.1028" />
        <parent link="base_link" />
        <child link="pole_bottom_1_link" />
    </joint>
    <link name="pole_bottom_1_link">
        <visual>
            <origin rpy="0 0 0" xyz="0 0 0" />
            <geometry>
                <mesh filename="package://turtlebot_description/meshes/stacks/hexagons/pole_bottom.dae" />
            </geometry>
        </visual>
        <collision>
            <origin rpy="0 0 0" xyz="0 0 0" />
            <geometry>
                <cylinder length="0.0492" radius="0.006" />
            </geometry>
        </collision>
        <inertial>
            <mass value="0.008" />
            <origin rpy="0 0 0" xyz="0 0 0" />
            <inertia ixx="0.000001686" ixy="0.0" ixz="0.0" iyy="0.000001686" iyz="0.0" izz="0.000000144" />
        </inertial>
    </link>
    <joint name="pole_bottom_2_joint" type="fixed">
        <origin rpy="0 0 0" xyz="-0.055 0.12 0.1028" />
        <parent link="base_link" />
        <child link="pole_bottom_2_link" />
    </joint>
    <link name="pole_bottom_2_link">
        <visual>
            <origin rpy="0 0 0" xyz="0 0 0" />
            <geometry>
                <mesh filename="package://turtlebot_description/meshes/stacks/hexagons/pole_bottom.dae" />
            </geometry>
        </visual>
        <collision>
            <origin rpy="0 0 0" xyz="0 0 0" />
            <geometry>
                <cylinder length="0.0492" radius="0.006" />
            </geometry>
        </collision>
        <inertial>
            <mass value="0.008" />
            <origin rpy="0 0 0" xyz="0 0 0" />
            <inertia ixx="0.000001686" ixy="0.0" ixz="0.0" iyy="0.000001686" iyz="0.0" izz="0.000000144" />
        </inertial>
    </link>
    <joint name="pole_bottom_3_joint" type="fixed">
        <origin rpy="0 0 0" xyz="0.12 -0.082 0.1028" />
        <parent link="base_link" />
        <child link="pole_bottom_3_link" />
    </joint>
    <link name="pole_bottom_3_link">
        <visual>
            <origin rpy="0 0 0" xyz="0 0 0" />
            <geometry>
                <mesh filename="package://turtlebot_description/meshes/stacks/hexagons/pole_bottom.dae" />
            </geometry>
        </visual>
        <collision>
            <origin rpy="0 0 0" xyz="0 0 0" />
            <geometry>
                <cylinder length="0.0492" radius="0.006" />
            </geometry>
        </collision>
        <inertial>
            <mass value="0.008" />
            <origin rpy="0 0 0" xyz="0 0 0" />
            <inertia ixx="0.000001686" ixy="0.0" ixz="0.0" iyy="0.000001686" iyz="0.0" izz="0.000000144" />
        </inertial>
    </link>
    <joint name="pole_bottom_4_joint" type="fixed">
        <origin rpy="0 0 0" xyz="0.055 -0.12 0.1028" />
        <parent link="base_link" />
        <child link="pole_bottom_4_link" />
    </joint>
    <link name="pole_bottom_4_link">
        <visual>
            <origin rpy="0 0 0" xyz="0 0 0" />
            <geometry>
                <mesh filename="package://turtlebot_description/meshes/stacks/hexagons/pole_bottom.dae" />
            </geometry>
        </visual>
        <collision>
            <origin rpy="0 0 0" xyz="0 0 0" />
            <geometry>
                <cylinder length="0.0492" radius="0.006" />
            </geometry>
        </collision>
        <inertial>
            <mass value="0.008" />
            <origin rpy="0 0 0" xyz="0 0 0" />
            <inertia ixx="0.000001686" ixy="0.0" ixz="0.0" iyy="0.000001686" iyz="0.0" izz="0.000000144" />
        </inertial>
    </link>
    <joint name="pole_bottom_5_joint" type="fixed">
        <origin rpy="0 0 0" xyz="-0.055 -0.12 0.1028" />
        <parent link="base_link" />
        <child link="pole_bottom_5_link" />
    </joint>
    <link name="pole_bottom_5_link">
        <visual>
            <origin rpy="0 0 0" xyz="0 0 0" />
            <geometry>
                <mesh filename="package://turtlebot_description/meshes/stacks/hexagons/pole_bottom.dae" />
            </geometry>
        </visual>
        <collision>
            <origin rpy="0 0 0" xyz="0 0 0" />
            <geometry>
                <cylinder length="0.0492" radius="0.006" />
            </geometry>
        </collision>
        <inertial>
            <mass value="0.008" />
            <origin rpy="0 0 0" xyz="0 0 0" />
            <inertia ixx="0.000001686" ixy="0.0" ixz="0.0" iyy="0.000001686" iyz="0.0" izz="0.000000144" />
        </inertial>
    </link>
    <joint name="plate_bottom_joint" type="fixed">
        <origin rpy="0 0 0" xyz="0.02364 0.0 0.1306" />
        <parent link="base_link" />
        <child link="plate_bottom_link" />
    </joint>
    <link name="plate_bottom_link">
        <visual>
            <origin rpy="0 0 0" xyz="0 0 0" />
            <geometry>
                <mesh filename="package://turtlebot_description/meshes/stacks/hexagons/plate_bottom.dae" />
            </geometry>
        </visual>
        <collision>
            <origin rpy="0 0 0" xyz="-0.02364 0 0" />
            <geometry>
                <cylinder length="0.006" radius="0.170" />
            </geometry>
        </collision>
        <inertial>
            <mass value="0.520" />
            <origin xyz="0 0 0" />
            <inertia ixx="0.003328" ixy="0.0" ixz="0.0" iyy="0.003328" iyz="0.0" izz="0.006656" />
        </inertial>
    </link>
    <joint name="pole_middle_0_joint" type="fixed">
        <origin rpy="0 0 0" xyz="0.0381 0.1505 0.164" />
        <parent link="base_link" />
        <child link="pole_middle_0_link" />
    </joint>
    <link name="pole_middle_0_link">
        <visual>
            <origin rpy="0 3.14159265359 0" xyz="0 0 0" />
            <geometry>
                <mesh filename="package://turtlebot_description/meshes/stacks/hexagons/pole_middle.dae" />
            </geometry>
        </visual>
        <collision>
            <origin rpy="0 0 0" xyz="0 0 0" />
            <geometry>
                <cylinder length="0.0608" radius="0.006" />
            </geometry>
        </collision>
        <inertial>
            <mass value="0.012" />
            <origin xyz="0 0 0" />
            <inertia ixx="0.000003805" ixy="0.0" ixz="0.0" iyy="0.000003805" iyz="0.0" izz="0.000000216" />
        </inertial>
    </link>
    <joint name="pole_middle_1_joint" type="fixed">
        <origin rpy="0 0 0" xyz="0.0381 -0.1505 0.164" />
        <parent link="base_link" />
        <child link="pole_middle_1_link" />
    </joint>
    <link name="pole_middle_1_link">
        <visual>
            <origin rpy="0 3.14159265359 0" xyz="0 0 0" />
            <geometry>
                <mesh filename="package://turtlebot_description/meshes/stacks/hexagons/pole_middle.dae" />
            </geometry>
        </visual>
        <collision>
            <origin rpy="0 0 0" xyz="0 0 0" />
            <geometry>
                <cylinder length="0.0608" radius="0.006" />
            </geometry>
        </collision>
        <inertial>
            <mass value="0.012" />
            <origin xyz="0 0 0" />
            <inertia ixx="0.000003805" ixy="0.0" ixz="0.0" iyy="0.000003805" iyz="0.0" izz="0.000000216" />
        </inertial>
    </link>
    <joint name="pole_middle_2_joint" type="fixed">
        <origin rpy="0 0 0" xyz="-0.0381 0.1505 0.164" />
        <parent link="base_link" />
        <child link="pole_middle_2_link" />
    </joint>
    <link name="pole_middle_2_link">
        <visual>
            <origin rpy="0 3.14159265359 0" xyz="0 0 0" />
            <geometry>
                <mesh filename="package://turtlebot_description/meshes/stacks/hexagons/pole_middle.dae" />
            </geometry>
        </visual>
        <collision>
            <origin rpy="0 0 0" xyz="0 0 0" />
            <geometry>
                <cylinder length="0.0608" radius="0.006" />
            </geometry>
        </collision>
        <inertial>
            <mass value="0.012" />
            <origin xyz="0 0 0" />
            <inertia ixx="0.000003805" ixy="0.0" ixz="0.0" iyy="0.000003805" iyz="0.0" izz="0.000000216" />
        </inertial>
    </link>
    <joint name="pole_middle_3_joint" type="fixed">
        <origin rpy="0 0 0" xyz="-0.0381 -0.1505 0.164" />
        <parent link="base_link" />
        <child link="pole_middle_3_link" />
    </joint>
    <link name="pole_middle_3_link">
        <visual>
            <origin rpy="0 3.14159265359 0" xyz="0 0 0" />
            <geometry>
                <mesh filename="package://turtlebot_description/meshes/stacks/hexagons/pole_middle.dae" />
            </geometry>
        </visual>
        <collision>
            <origin rpy="0 0 0" xyz="0 0 0" />
            <geometry>
                <cylinder length="0.0608" radius="0.006" />
            </geometry>
        </collision>
        <inertial>
            <mass value="0.012" />
            <origin xyz="0 0 0" />
            <inertia ixx="0.000003805" ixy="0.0" ixz="0.0" iyy="0.000003805" iyz="0.0" izz="0.000000216" />
        </inertial>
    </link>
    <joint name="plate_middle_joint" type="fixed">
        <origin rpy="0 0 0" xyz="-0.01364 0.0 0.1874" />
        <parent link="base_link" />
        <child link="plate_middle_link" />
    </joint>
    <link name="plate_middle_link">
        <visual>
            <origin rpy="0 0 0" xyz="0 0 0" />
            <geometry>
                <mesh filename="package://turtlebot_description/meshes/stacks/hexagons/plate_middle.dae" />
            </geometry>
        </visual>
        <collision>
            <origin rpy="0 0 0" xyz="0.01364 0.0 0.0" />
            <geometry>
                <cylinder length="0.006" radius="0.170" />
            </geometry>
        </collision>
        <inertial>
            <mass value="0.520" />
            <origin xyz="0 0 0" />
            <inertia ixx="0.003328" ixy="0.0" ixz="0.0" iyy="0.003328" iyz="0.0" izz="0.006656" />
        </inertial>
    </link>
    <joint name="pole_top_0_joint" type="fixed">
        <origin rpy="0 0 0" xyz="0.0381 0.1505 0.292" />
        <parent link="base_link" />
        <child link="pole_top_0_link" />
    </joint>
    <link name="pole_top_0_link">
        <visual>
            <origin rpy="0 0 0" xyz=" 0 0 0" />
            <geometry>
                <mesh filename="package://turtlebot_description/meshes/stacks/hexagons/pole_top.dae" />
            </geometry>
        </visual>
        <collision>
            <origin rpy="0 0 0" xyz="0 0 0" />
            <geometry>
                <cylinder length="0.2032" radius="0.006" />
            </geometry>
        </collision>
        <inertial>
            <mass value="0.060" />
            <origin xyz="0 0 0" />
            <inertia ixx="0.000206991" ixy="0.0" ixz="0.0" iyy="0.000206991" iyz="0.0" izz="0.000001080" />
        </inertial>
    </link>
    <joint name="pole_top_1_joint" type="fixed">
        <origin rpy="0 0 0" xyz="0.0381 -0.1505 0.292" />
        <parent link="base_link" />
        <child link="pole_top_1_link" />
    </joint>
    <link name="pole_top_1_link">
        <visual>
            <origin rpy="0 0 0" xyz=" 0 0 0" />
            <geometry>
                <mesh filename="package://turtlebot_description/meshes/stacks/hexagons/pole_top.dae" />
            </geometry>
        </visual>
        <collision>
            <origin rpy="0 0 0" xyz="0 0 0" />
            <geometry>
                <cylinder length="0.2032" radius="0.006" />
            </geometry>
        </collision>
        <inertial>
            <mass value="0.060" />
            <origin xyz="0 0 0" />
            <inertia ixx="0.000206991" ixy="0.0" ixz="0.0" iyy="0.000206991" iyz="0.0" izz="0.000001080" />
        </inertial>
    </link>
    <joint name="pole_top_2_joint" type="fixed">
        <origin rpy="0 0 0" xyz="-0.0381 0.1505 0.292" />
        <parent link="base_link" />
        <child link="pole_top_2_link" />
    </joint>
    <link name="pole_top_2_link">
        <visual>
            <origin rpy="0 0 0" xyz=" 0 0 0" />
            <geometry>
                <mesh filename="package://turtlebot_description/meshes/stacks/hexagons/pole_top.dae" />
            </geometry>
        </visual>
        <collision>
            <origin rpy="0 0 0" xyz="0 0 0" />
            <geometry>
                <cylinder length="0.2032" radius="0.006" />
            </geometry>
        </collision>
        <inertial>
            <mass value="0.060" />
            <origin xyz="0 0 0" />
            <inertia ixx="0.000206991" ixy="0.0" ixz="0.0" iyy="0.000206991" iyz="0.0" izz="0.000001080" />
        </inertial>
    </link>
    <joint name="pole_top_3_joint" type="fixed">
        <origin rpy="0 0 0" xyz="-0.0381 -0.1505 0.292" />
        <parent link="base_link" />
        <child link="pole_top_3_link" />
    </joint>
    <link name="pole_top_3_link">
        <visual>
            <origin rpy="0 0 0" xyz=" 0 0 0" />
            <geometry>
                <mesh filename="package://turtlebot_description/meshes/stacks/hexagons/pole_top.dae" />
            </geometry>
        </visual>
        <collision>
            <origin rpy="0 0 0" xyz="0 0 0" />
            <geometry>
                <cylinder length="0.2032" radius="0.006" />
            </geometry>
        </collision>
        <inertial>
            <mass value="0.060" />
            <origin xyz="0 0 0" />
            <inertia ixx="0.000206991" ixy="0.0" ixz="0.0" iyy="0.000206991" iyz="0.0" izz="0.000001080" />
        </inertial>
    </link>
    <joint name="pole_kinect_0_joint" type="fixed">
        <origin rpy="0 0 0" xyz="-0.1024 0.098 0.2372" />
        <parent link="base_link" />
        <child link="pole_kinect_0_link" />
    </joint>
    <link name="pole_kinect_0_link">
        <visual>
            <origin rpy="0 0 0" xyz="0 0 -0.01" />
            <geometry>
                <mesh filename="package://turtlebot_description/meshes/sensors/sensor_pole.dae" />
            </geometry>
        </visual>
        <collision>
            <origin rpy="0 0 0" xyz="0 0 0" />
            <geometry>
                <cylinder length="0.0936" radius="0.006" />
            </geometry>
        </collision>
        <inertial>
            <mass value="0.020" />
            <origin xyz="0 0 0" />
            <inertia ixx="0.000014782" ixy="0.0" ixz="0.0" iyy="0.000014782" iyz="0.0" izz="0.000000360" />
        </inertial>
    </link>
    <joint name="pole_kinect_1_joint" type="fixed">
        <origin rpy="0 0 0" xyz="-0.1024 -0.098 0.2372" />
        <parent link="base_link" />
        <child link="pole_kinect_1_link" />
    </joint>
    <link name="pole_kinect_1_link">
        <visual>
            <origin rpy="0 0 0" xyz="0 0 -0.01" />
            <geometry>
                <mesh filename="package://turtlebot_description/meshes/sensors/sensor_pole.dae" />
            </geometry>
        </visual>
        <collision>
            <origin rpy="0 0 0" xyz="0 0 0" />
            <geometry>
                <cylinder length="0.0936" radius="0.006" />
            </geometry>
        </collision>
        <inertial>
            <mass value="0.020" />
            <origin xyz="0 0 0" />
            <inertia ixx="0.000014782" ixy="0.0" ixz="0.0" iyy="0.000014782" iyz="0.0" izz="0.000000360" />
        </inertial>
    </link>
    <joint name="plate_top_joint" type="fixed">
        <origin rpy="0 0 0" xyz="-0.01364 0.0  0.3966" />
        <parent link="base_link" />
        <child link="plate_top_link" />
    </joint>
    <link name="plate_top_link">
        <visual>
            <origin rpy="0 0 0" xyz="0 0 0" />
            <geometry>
                <mesh filename="package://turtlebot_description/meshes/stacks/hexagons/plate_top.dae" />
            </geometry>
        </visual>
        <collision>
            <origin rpy="0 0 0" xyz="0.01364 0 0" />
            <geometry>
                <cylinder length="0.006" radius="0.170" />
            </geometry>
        </collision>
        <inertial>
            <mass value="0.520" />
            <origin xyz="0 0 0" />
            <inertia ixx="0.003328" ixy="0.0" ixz="0.0" iyy="0.003328" iyz="0.0" izz="0.006656" />
        </inertial>
    </link>
    <link name="base_footprint" />
    <!--
       Base link is set at the bottom of the base mould.
       This is done to be compatible with the way base link
       was configured for turtlebot 1. Refer to

       https://github.com/turtlebot/turtlebot/issues/40

       To put the base link at the more oft used wheel
       axis, set the z-distance from the base_footprint
       to 0.352.
      -->
    <joint name="base_joint" type="fixed">
        <origin rpy="0 0 0" xyz="0 0 0.0102" />
        <parent link="base_footprint" />
        <child link="base_link" />
    </joint>
    <link name="base_link">
        <visual>
            <geometry>
                <!-- new mesh -->
                <mesh filename="package://kobuki_description/meshes/main_body.dae" />
            </geometry>
            <origin rpy="0 0 0" xyz="0.001 0 0.05199" />
        </visual>
        <collision name="base">
            <geometry>
                <cylinder length="0.10938" radius="0.178" />
            </geometry>
            <origin rpy="0 0 0" xyz="0.0 0 0.05949" />
        </collision>
        <inertial>
            <!-- COM experimentally determined -->
            <origin xyz="0.01 0 0" />
            <mass value="2.4" />
            <!-- 2.4/2.6 kg for small/big battery pack -->
            <!-- Kobuki's inertia tensor is approximated by a cylinder with homogeneous mass distribution
             More details: http://en.wikipedia.org/wiki/List_of_moment_of_inertia_tensors
             m = 2.4 kg; h = 0.09 m; r = 0.175 m
             ixx = 1/12 * m * (3 * r^2 + h^2)
             iyy = 1/12 * m * (3 * r^2 + h^2)
             izz = 1/2 * m * r^2
          -->
            <inertia ixx="0.019995" ixy="0.0" ixz="0.0" iyy="0.019995" iyz="0.0" izz="0.03675" />
        </inertial>
    </link>
    <joint name="wheel_left_joint" type="continuous">
        <parent link="base_link" />
        <child link="wheel_left_link" />
        <origin rpy="-1.57079632679 0 0" xyz="0.00 0.115 0.0250" />
        <axis xyz="0 0 1" />
    </joint>
    <link name="wheel_left_link">
        <visual>
            <geometry>
                <mesh filename="package://kobuki_description/meshes/wheel.dae" />
            </geometry>
            <origin rpy="0 0 0" xyz="0 0 0" />
        </visual>
        <collision>
            <geometry>
                <cylinder length="0.0206" radius="0.0352" />
            </geometry>
            <origin rpy="0 0 0" xyz="0 0 0" />
        </collision>
        <inertial>
            <mass value="0.01" />
            <origin xyz="0 0 0" />
            <inertia ixx="0.001" ixy="0.0" ixz="0.0" iyy="0.001" iyz="0.0" izz="0.001" />
        </inertial>
    </link>
    <joint name="wheel_right_joint" type="continuous">
        <parent link="base_link" />
        <child link="wheel_right_link" />
        <origin rpy="-1.57079632679 0 0" xyz="0.00 -0.115 0.0250" />
        <axis xyz="0 0 1" />
    </joint>
    <link name="wheel_right_link">
        <visual>
            <geometry>
                <mesh filename="package://kobuki_description/meshes/wheel.dae" />
            </geometry>
            <origin rpy="0 0 0" xyz="0 0 0" />
        </visual>
        <collision>
            <geometry>
                <cylinder length="0.0206" radius="0.0350" />
            </geometry>
            <origin rpy="0 0 0" xyz="0 0 0" />
        </collision>
        <inertial>
            <mass value="0.01" />
            <origin xyz="0 0 0" />
            <inertia ixx="0.001" ixy="0.0" ixz="0.0" iyy="0.001" iyz="0.0" izz="0.001" />
        </inertial>
    </link>
    <joint name="caster_front_joint" type="fixed">
        <parent link="base_link" />
        <child link="caster_front_link" />
        <origin rpy="-1.57079632679 0 0" xyz="0.115 0.0 0.007" />
    </joint>
    <link name="caster_front_link">
        <collision>
            <geometry>
                <cylinder length="0.0176" radius="0.017" />
            </geometry>
            <origin rpy="0 0 0" xyz="0 0 0" />
        </collision>
        <inertial>
            <mass value="0.01" />
            <origin xyz="0 0 0" />
            <inertia ixx="0.001" ixy="0.0" ixz="0.0" iyy="0.001" iyz="0.0" izz="0.001" />
        </inertial>
    </link>
    <joint name="caster_back_joint" type="fixed">
        <parent link="base_link" />
        <child link="caster_back_link" />
        <origin rpy="-1.57079632679 0 0" xyz="-0.135 0.0 0.009" />
    </joint>
    <link name="caster_back_link">
        <collision>
            <geometry>
                <cylinder length="0.0176" radius="0.017" />
            </geometry>
            <origin rpy="0 0 0" xyz="0 0 0" />
        </collision>
        <inertial>
            <mass value="0.01" />
            <origin xyz="0 0 0" />
            <inertia ixx="0.001" ixy="0.0" ixz="0.0" iyy="0.001" iyz="0.0" izz="0.001" />
        </inertial>
    </link>
    <!-- Kobuki's sensors -->
    <joint name="gyro_joint" type="fixed">
        <axis xyz="0 1 0" />
        <origin rpy="0 0 0" xyz="0.056 0.062 0.0202" />
        <parent link="base_link" />
        <child link="gyro_link" />
    </joint>
    <link name="gyro_link">
        <inertial>
            <mass value="0.001" />
            <origin rpy="0 0 0" xyz="0 0 0" />
            <inertia ixx="0.0001" ixy="0" ixz="0" iyy="0.000001" iyz="0" izz="0.0001" />
        </inertial>
    </link>
    <joint name="cliff_sensor_left_joint" type="fixed">
        <origin rpy="0 1.57079632679 0" xyz="0.08734 0.13601 0.0214" />
        <parent link="base_link" />
        <child link="cliff_sensor_left_link" />
    </joint>
    <link name="cliff_sensor_left_link">
        <inertial>
            <mass value="0.0001" />
            <origin xyz="0 0 0" />
            <inertia ixx="0.0001" ixy="0.0" ixz="0.0" iyy="0.0001" iyz="0.0" izz="0.0001" />
        </inertial>
    </link>
    <joint name="cliff_sensor_right_joint" type="fixed">
        <origin rpy="0 1.57079632679 0" xyz="0.085 -0.13601 0.0214" />
        <parent link="base_link" />
        <child link="cliff_sensor_right_link" />
    </joint>
    <link name="cliff_sensor_right_link">
        <inertial>
            <mass value="0.0001" />
            <origin xyz="0 0 0" />
            <inertia ixx="0.0001" ixy="0.0" ixz="0.0" iyy="0.0001" iyz="0.0" izz="0.0001" />
        </inertial>
    </link>
    <joint name="cliff_sensor_front_joint" type="fixed">
        <origin rpy="0 1.57079632679 0" xyz="0.156 0.00 0.0214" />
        <parent link="base_link" />
        <child link="cliff_sensor_front_link" />
    </joint>
    <link name="cliff_sensor_front_link">
        <inertial>
            <mass value="0.0001" />
            <origin xyz="0 0 0" />
            <inertia ixx="0.0001" ixy="0.0" ixz="0.0" iyy="0.0001" iyz="0.0" izz="0.0001" />
        </inertial>
    </link>
    <gazebo reference="wheel_left_link">
        <mu1>1.0</mu1>
        <mu2>1.0</mu2>
        <kp>1000000.0</kp>
        <kd>100.0</kd>
        <minDepth>0.001</minDepth>
        <maxVel>1.0</maxVel>
    </gazebo>
    <gazebo reference="wheel_right_link">
        <mu1>1.0</mu1>
        <mu2>1.0</mu2>
        <kp>1000000.0</kp>
        <kd>100.0</kd>
        <minDepth>0.001</minDepth>
        <maxVel>1.0</maxVel>
    </gazebo>
    <gazebo reference="caster_front_link">
        <mu1>0.0</mu1>
        <mu2>0.0</mu2>
        <kp>1000000.0</kp>
        <kd>100.0</kd>
        <minDepth>0.001</minDepth>
        <maxVel>1.0</maxVel>
    </gazebo>
    <gazebo reference="caster_back_link">
        <mu1>0.0</mu1>
        <mu2>0.0</mu2>
        <kp>1000000.0</kp>
        <kd>100.0</kd>
        <minDepth>0.001</minDepth>
        <maxVel>1.0</maxVel>
    </gazebo>
    <gazebo reference="base_link">
        <mu1>0.3</mu1>
        <mu2>0.3</mu2>
        <sensor name="bumpers" type="contact">
            <always_on>1</always_on>
            <update_rate>50.0</update_rate>
            <visualize>true</visualize>
            <contact>
                <collision>base_footprint_fixed_joint_lump__base_collision</collision>
            </contact>
        </sensor>
    </gazebo>
    <gazebo reference="cliff_sensor_left_link">
        <sensor name="cliff_sensor_left" type="ray">
            <always_on>true</always_on>
            <update_rate>50</update_rate>
            <visualize>true</visualize>
            <ray>
                <scan>
                    <horizontal>
                        <samples>50</samples>
                        <resolution>1.0</resolution>
                        <min_angle>-0.0436</min_angle>
                        <!-- -2.5 degree -->
                        <max_angle>0.0436</max_angle>
                        <!-- 2.5 degree -->
                    </horizontal>
                    <!--            Can't use vertical rays until this bug is resolved: -->
                    <!--            https://bitbucket.org/osrf/gazebo/issue/509/vertical-sensor-doesnt-works -->
                    <!-- 	          <vertical> -->
                    <!-- 	            <samples>50</samples> -->
                    <!-- 	            <resolution>1.0</resolution> -->
                    <!-- 	            <min_angle>-0.0436</min_angle>  -2.5 degree -->
                    <!-- 	            <max_angle>0.0436</max_angle> 2.5 degree -->
                    <!-- 	          </vertical> -->
                </scan>
                <range>
                    <min>0.01</min>
                    <max>0.15</max>
                    <resolution>1.0</resolution>
                </range>
            </ray>
        </sensor>
    </gazebo>
    <gazebo reference="cliff_sensor_right_link">
        <sensor name="cliff_sensor_right" type="ray">
            <always_on>true</always_on>
            <update_rate>50</update_rate>
            <visualize>true</visualize>
            <ray>
                <scan>
                    <horizontal>
                        <samples>50</samples>
                        <resolution>1.0</resolution>
                        <min_angle>-0.0436</min_angle>
                        <!-- -2.5 degree -->
                        <max_angle>0.0436</max_angle>
                        <!-- 2.5 degree -->
                    </horizontal>
                    <!--            Can't use vertical rays until this bug is resolved: -->
                    <!--            https://bitbucket.org/osrf/gazebo/issue/509/vertical-sensor-doesnt-works -->
                    <!-- 	          <vertical> -->
                    <!-- 	            <samples>50</samples> -->
                    <!-- 	            <resolution>1.0</resolution> -->
                    <!-- 	            <min_angle>-0.0436</min_angle>  -2.5 degree -->
                    <!-- 	            <max_angle>0.0436</max_angle> 2.5 degree -->
                    <!-- 	          </vertical> -->
                </scan>
                <range>
                    <min>0.01</min>
                    <max>0.15</max>
                    <resolution>1.0</resolution>
                </range>
            </ray>
        </sensor>
    </gazebo>
    <gazebo reference="cliff_sensor_front_link">
        <sensor name="cliff_sensor_front" type="ray">
            <always_on>true</always_on>
            <update_rate>50</update_rate>
            <visualize>true</visualize>
            <ray>
                <scan>
                    <horizontal>
                        <samples>50</samples>
                        <resolution>1.0</resolution>
                        <min_angle>-0.0436</min_angle>
                        <!-- -2.5 degree -->
                        <max_angle>0.0436</max_angle>
                        <!-- 2.5 degree -->
                    </horizontal>
                    <!-- 	          Can't use vertical rays until this bug is resolved: -->
                    <!--            https://bitbucket.org/osrf/gazebo/issue/509/vertical-sensor-doesnt-works -->
                    <!-- 	          <vertical> -->
                    <!-- 	            <samples>50</samples> -->
                    <!-- 	            <resolution>1.0</resolution> -->
                    <!-- 	            <min_angle>-0.0436</min_angle>  -2.5 degree -->
                    <!-- 	            <max_angle>0.0436</max_angle> 2.5 degree -->
                    <!-- 	          </vertical> -->
                </scan>
                <range>
                    <min>0.01</min>
                    <max>0.15</max>
                    <resolution>1.0</resolution>
                </range>
            </ray>
        </sensor>
    </gazebo>
    <gazebo reference="gyro_link">
        <sensor name="imu" type="imu">
            <always_on>true</always_on>
            <update_rate>50</update_rate>
            <visualize>false</visualize>
            <imu>
                <noise>
                    <type>gaussian</type>
                    <rate>
                        <mean>0.0</mean>
                        <stddev>1.96e-06</stddev>
                        <!-- 0.25 x 0.25 (deg/s) -->
                        <bias_mean>0.0</bias_mean>
                        <bias_stddev>0.0</bias_stddev>
                    </rate>
                    <accel>
                        <!-- not used in the plugin and real robot, hence using tutorial values -->
                        <mean>0.0</mean>
                        <stddev>1.7e-2</stddev>
                        <bias_mean>0.1</bias_mean>
                        <bias_stddev>0.001</bias_stddev>
                    </accel>
                </noise>
            </imu>
        </sensor>
    </gazebo>
    <gazebo>
        <plugin filename="libgazebo_ros_kobuki.so" name="kobuki_controller">
            <publish_tf>1</publish_tf>
            <left_wheel_joint_name>wheel_left_joint</left_wheel_joint_name>
            <right_wheel_joint_name>wheel_right_joint</right_wheel_joint_name>
            <wheel_separation>.230</wheel_separation>
            <wheel_diameter>0.070</wheel_diameter>
            <torque>1.0</torque>
            <velocity_command_timeout>0.6</velocity_command_timeout>
            <cliff_sensor_left_name>cliff_sensor_left</cliff_sensor_left_name>
            <cliff_sensor_center_name>cliff_sensor_front</cliff_sensor_center_name>
            <cliff_sensor_right_name>cliff_sensor_right</cliff_sensor_right_name>
            <cliff_detection_threshold>0.04</cliff_detection_threshold>
            <bumper_name>bumpers</bumper_name>
            <imu_name>imu</imu_name>
        </plugin>
    </gazebo>
    <!-- <link name="kinect_adjust_link"/>
  <joint name="kinect_adjust" type="floating">
    <origin xyz="0 0 0" rpy="0 0 0"/>
    <parent link="base_footprint"/>
    <child link="kinect_adjust_link"/>
    <limit effort="10" lower="-0.2" upper="0.2"/>
  </joint> -->
    <joint name="camera_rgb_joint" type="fixed">
        <origin rpy="3.14 0.475 0" xyz="0.03 -0.0125 0.3" />
        <parent link="base_footprint" />
        <child link="camera_rgb_frame" />
    </joint>
    <link name="camera_rgb_frame" />
    <joint name="camera_rgb_optical_joint" type="fixed">
        <origin rpy="-1.57079632679 0 -1.57079632679" xyz="0 0 0" />
        <parent link="camera_rgb_frame" />
        <child link="camera_rgb_optical_frame" />
    </joint>
    <link name="camera_rgb_optical_frame" />
    <joint name="camera_joint" type="fixed">
        <origin rpy="0 0 0" xyz="-0.031 0.0125 -0.016" />
        <parent link="camera_rgb_frame" />
        <child link="camera_link" />
    </joint>
    <link name="camera_link">
        <visual>
            <origin rpy="0 0 1.57079632679" xyz="0 0 0" />
            <geometry>
                <mesh filename="package://turtlebot_description/meshes/sensors/kinect.dae" />
            </geometry>
        </visual>
        <collision>
            <origin rpy="0 0 0" xyz="0.0 0.0 0.0" />
            <geometry>
                <box size="0.07271 0.27794 0.073" />
            </geometry>
        </collision>
        <inertial>
            <mass value="0.564" />
            <origin xyz="0 0 0" />
            <inertia ixx="0.003881243" ixy="0.0" ixz="0.0" iyy="0.000498940" iyz="0.0" izz="0.003879257" />
        </inertial>
    </link>
    <!-- The fixed joints & links below are usually published by static_transformers launched by the OpenNi launch 
         files. However, for Gazebo simulation we need them, so we add them here.
         (Hence, don't publish them additionally!) -->
    <joint name="camera_depth_joint" type="fixed">
        <origin rpy="0 0 0" xyz="0 0.025 0" />
        <parent link="camera_rgb_frame" />
        <child link="camera_depth_frame" />
    </joint>
    <link name="camera_depth_frame" />
    <joint name="camera_depth_optical_joint" type="fixed">
        <origin rpy="-1.57079632679 0 -1.57079632679" xyz="0 0 0" />
        <parent link="camera_depth_frame" />
        <child link="camera_depth_optical_frame" />
    </joint>
    <link name="camera_depth_optical_frame" />
    <gazebo reference="camera_link">
        <sensor name="camera" type="depth">
            <always_on>true</always_on>
            <update_rate>20.0</update_rate>
            <camera>
                <horizontal_fov>1.0471975512</horizontal_fov>
                <image>
                    <format>B8G8R8</format>
                    <width>640</width>
                    <height>480</height>
                </image>
                <clip>
                    <near>0.05</near>
                    <far>8.0</far>
                </clip>
            </camera>
            <plugin filename="libgazebo_ros_openni_kinect.so" name="kinect_camera_controller">
                <cameraName>camera</cameraName>
                <alwaysOn>true</alwaysOn>
                <updateRate>10</updateRate>
                <imageTopicName>rgb/image_raw</imageTopicName>
                <depthImageTopicName>depth/image_raw</depthImageTopicName>
                <pointCloudTopicName>depth/points</pointCloudTopicName>
                <cameraInfoTopicName>rgb/camera_info</cameraInfoTopicName>
                <depthImageCameraInfoTopicName>depth/camera_info</depthImageCameraInfoTopicName>
                <frameName>camera_depth_optical_frame</frameName>
                <baseline>0.1</baseline>
                <distortion_k1>0.0</distortion_k1>
                <distortion_k2>0.0</distortion_k2>
                <distortion_k3>0.0</distortion_k3>
                <distortion_t1>0.0</distortion_t1>
                <distortion_t2>0.0</distortion_t2>
                <pointCloudCutoff>0.4</pointCloudCutoff>
            </plugin>
        </sensor>
    </gazebo>
    <link name="laser">
        <collision>
            <origin rpy="0 0 0" xyz="0 0 0" />
            <geometry>
                <box size="0.1 0.1 0.1" />
            </geometry>
        </collision>
        <visual>
            <origin rpy="0 0 0" xyz="0 0 0" />
            <geometry>
                <mesh filename="package://lidar_description/mesh/hokuyo.dae" />
            </geometry>
        </visual>
        <inertial>
            <mass value="1e-5" />
            <origin rpy="0 0 0" xyz="0 0 0" />
            <inertia ixx="1e-6" ixy="0" ixz="0" iyy="1e-6" iyz="0" izz="1e-6" />
        </inertial>
    </link>
    <joint name="hokuyo_joint" type="fixed">
        <axis xyz="0 0 1" />
        <origin rpy="0 0 0" xyz="0 0 0.035" />
        <parent link="plate_top_link" />
        <child link="laser" />
    </joint>
    <transmission name="trans_joint1">
        <type>transmission_interface/SimpleTransmission</type>
        <joint name="joint1">
            <hardwareInterface>hardware_interface/EffortJointInterface</hardwareInterface>
        </joint>
        <actuator name="joint1_motor">
            <hardwareInterface>hardware_interface/EffortJointInterface</hardwareInterface>
            <mechanicalReduction>1</mechanicalReduction>
        </actuator>
    </transmission>
    <transmission name="trans_joint2">
        <type>transmission_interface/SimpleTransmission</type>
        <joint name="joint2">
            <hardwareInterface>hardware_interface/EffortJointInterface</hardwareInterface>
        </joint>
        <actuator name="joint2_motor">
            <hardwareInterface>hardware_interface/EffortJointInterface</hardwareInterface>
            <mechanicalReduction>1</mechanicalReduction>
        </actuator>
    </transmission>
    <transmission name="trans_joint3">
        <type>transmission_interface/SimpleTransmission</type>
        <joint name="joint3">
            <hardwareInterface>hardware_interface/EffortJointInterface</hardwareInterface>
        </joint>
        <actuator name="joint3_motor">
            <hardwareInterface>hardware_interface/EffortJointInterface</hardwareInterface>
            <mechanicalReduction>1</mechanicalReduction>
        </actuator>
    </transmission>
    <transmission name="trans_joint4">
        <type>transmission_interface/SimpleTransmission</type>
        <joint name="joint4">
            <hardwareInterface>hardware_interface/EffortJointInterface</hardwareInterface>
        </joint>
        <actuator name="joint4_motor">
            <hardwareInterface>hardware_interface/EffortJointInterface</hardwareInterface>
            <mechanicalReduction>1</mechanicalReduction>
        </actuator>
    </transmission>
    <transmission name="trans_gripper">
        <type>transmission_interface/SimpleTransmission</type>
        <joint name="gripper">
            <hardwareInterface>hardware_interface/EffortJointInterface</hardwareInterface>
        </joint>
        <actuator name="gripper_motor">
            <hardwareInterface>hardware_interface/EffortJointInterface</hardwareInterface>
            <mechanicalReduction>1</mechanicalReduction>
        </actuator>
    </transmission>
    <transmission name="trans_gripper_sub">
        <type>transmission_interface/SimpleTransmission</type>
        <joint name="gripper_sub">
            <hardwareInterface>hardware_interface/EffortJointInterface</hardwareInterface>
        </joint>
        <actuator name="gripper_sub_motor">
            <hardwareInterface>hardware_interface/EffortJointInterface</hardwareInterface>
            <mechanicalReduction>1</mechanicalReduction>
        </actuator>
    </transmission>
    <transmission name="trans_wheel_left_joint">
        <type>transmission_interface/SimpleTransmission</type>
        <joint name="wheel_left_joint">
            <hardwareInterface>hardware_interface/EffortJointInterface</hardwareInterface>
        </joint>
        <actuator name="wheel_left_joint_motor">
            <hardwareInterface>hardware_interface/EffortJointInterface</hardwareInterface>
            <mechanicalReduction>1</mechanicalReduction>
        </actuator>
    </transmission>
    <transmission name="trans_wheel_right_joint">
        <type>transmission_interface/SimpleTransmission</type>
        <joint name="wheel_right_joint">
            <hardwareInterface>hardware_interface/EffortJointInterface</hardwareInterface>
        </joint>
        <actuator name="wheel_right_joint_motor">
            <hardwareInterface>hardware_interface/EffortJointInterface</hardwareInterface>
            <mechanicalReduction>1</mechanicalReduction>
        </actuator>
    </transmission>
    <gazebo>
        <plugin name="gazebo_ros_control" filename="libgazebo_ros_control.so">
            <robotNamespace>/</robotNamespace>
        </plugin>
    </gazebo>
</robot>